Not Found: /favicon.ico
"GET /favicon.ico HTTP/1.1" 404 2080
Not Found: /
"GET / HTTP/1.1" 404 2029
Not Found: /api/tras=nsaction/
"GET /api/tras=nsaction/ HTTP/1.1" 404 3790
Not Found: /api/transaction/
"GET /api/transaction/ HTTP/1.1" 404 3782
Internal Server Error: /api/transactions/
Traceback (most recent call last):
  File "C:\Users\takud\OneDrive\Documents\Development\Intelli-Pos\intelliPos\venv\lib\site-packages\django\core\handlers\exception.py", line 47, in inner
    response = get_response(request)
  File "C:\Users\takud\OneDrive\Documents\Development\Intelli-Pos\intelliPos\venv\lib\site-packages\django\core\handlers\base.py", line 181, in _get_response
    response = wrapped_callback(request, *callback_args, **callback_kwargs)
  File "C:\Users\takud\OneDrive\Documents\Development\Intelli-Pos\intelliPos\venv\lib\site-packages\django\views\decorators\csrf.py", line 54, in wrapped_view
    return view_func(*args, **kwargs)
  File "C:\Users\takud\OneDrive\Documents\Development\Intelli-Pos\intelliPos\venv\lib\site-packages\django\views\generic\base.py", line 70, in view
    return self.dispatch(request, *args, **kwargs)
  File "C:\Users\takud\OneDrive\Documents\Development\Intelli-Pos\intelliPos\venv\lib\site-packages\rest_framework\views.py", line 509, in dispatch
    response = self.handle_exception(exc)
  File "C:\Users\takud\OneDrive\Documents\Development\Intelli-Pos\intelliPos\venv\lib\site-packages\rest_framework\views.py", line 469, in handle_exception
    self.raise_uncaught_exception(exc)
  File "C:\Users\takud\OneDrive\Documents\Development\Intelli-Pos\intelliPos\venv\lib\site-packages\rest_framework\views.py", line 480, in raise_uncaught_exception
    raise exc
  File "C:\Users\takud\OneDrive\Documents\Development\Intelli-Pos\intelliPos\venv\lib\site-packages\rest_framework\views.py", line 497, in dispatch
    self.initial(request, *args, **kwargs)
  File "C:\Users\takud\OneDrive\Documents\Development\Intelli-Pos\intelliPos\venv\lib\site-packages\rest_framework\views.py", line 415, in initial
    self.check_permissions(request)
  File "C:\Users\takud\OneDrive\Documents\Development\Intelli-Pos\intelliPos\venv\lib\site-packages\rest_framework\views.py", line 332, in check_permissions
    if not permission.has_permission(request, self):
  File "C:\Users\takud\OneDrive\Documents\Development\Intelli-Pos\intelliPos\venv\lib\site-packages\rest_framework\permissions.py", line 229, in has_permission
    queryset = self._queryset(view)
  File "C:\Users\takud\OneDrive\Documents\Development\Intelli-Pos\intelliPos\venv\lib\site-packages\rest_framework\permissions.py", line 209, in _queryset
    ).format(self.__class__.__name__)
AssertionError: Cannot apply DjangoModelPermissionsOrAnonReadOnly on a view that does not set `.queryset` or have a `.get_queryset()` method.
"GET /api/transactions/ HTTP/1.1" 500 111621
Not Found: /api/api-auth/
"GET /api/api-auth/ HTTP/1.1" 404 4069
Not Found: /api/api_auth
"GET /api/api_auth HTTP/1.1" 404 3770
Not Found: /api/api-auth/
"GET /api/api-auth/ HTTP/1.1" 404 4069
Not Found: /accounts/profile/
"GET /accounts/profile/ HTTP/1.1" 404 2098
Internal Server Error: /api/transactions/
Traceback (most recent call last):
  File "C:\Users\takud\OneDrive\Documents\Development\Intelli-Pos\intelliPos\venv\lib\site-packages\django\core\handlers\exception.py", line 47, in inner
    response = get_response(request)
  File "C:\Users\takud\OneDrive\Documents\Development\Intelli-Pos\intelliPos\venv\lib\site-packages\django\core\handlers\base.py", line 181, in _get_response
    response = wrapped_callback(request, *callback_args, **callback_kwargs)
  File "C:\Users\takud\OneDrive\Documents\Development\Intelli-Pos\intelliPos\venv\lib\site-packages\django\views\decorators\csrf.py", line 54, in wrapped_view
    return view_func(*args, **kwargs)
  File "C:\Users\takud\OneDrive\Documents\Development\Intelli-Pos\intelliPos\venv\lib\site-packages\django\views\generic\base.py", line 70, in view
    return self.dispatch(request, *args, **kwargs)
  File "C:\Users\takud\OneDrive\Documents\Development\Intelli-Pos\intelliPos\venv\lib\site-packages\rest_framework\views.py", line 509, in dispatch
    response = self.handle_exception(exc)
  File "C:\Users\takud\OneDrive\Documents\Development\Intelli-Pos\intelliPos\venv\lib\site-packages\rest_framework\views.py", line 469, in handle_exception
    self.raise_uncaught_exception(exc)
  File "C:\Users\takud\OneDrive\Documents\Development\Intelli-Pos\intelliPos\venv\lib\site-packages\rest_framework\views.py", line 480, in raise_uncaught_exception
    raise exc
  File "C:\Users\takud\OneDrive\Documents\Development\Intelli-Pos\intelliPos\venv\lib\site-packages\rest_framework\views.py", line 497, in dispatch
    self.initial(request, *args, **kwargs)
  File "C:\Users\takud\OneDrive\Documents\Development\Intelli-Pos\intelliPos\venv\lib\site-packages\rest_framework\views.py", line 415, in initial
    self.check_permissions(request)
  File "C:\Users\takud\OneDrive\Documents\Development\Intelli-Pos\intelliPos\venv\lib\site-packages\rest_framework\views.py", line 332, in check_permissions
    if not permission.has_permission(request, self):
  File "C:\Users\takud\OneDrive\Documents\Development\Intelli-Pos\intelliPos\venv\lib\site-packages\rest_framework\permissions.py", line 229, in has_permission
    queryset = self._queryset(view)
  File "C:\Users\takud\OneDrive\Documents\Development\Intelli-Pos\intelliPos\venv\lib\site-packages\rest_framework\permissions.py", line 209, in _queryset
    ).format(self.__class__.__name__)
AssertionError: Cannot apply DjangoModelPermissionsOrAnonReadOnly on a view that does not set `.queryset` or have a `.get_queryset()` method.
"GET /api/transactions/ HTTP/1.1" 500 111621
Internal Server Error: /api/transactions/
Traceback (most recent call last):
  File "C:\Users\takud\OneDrive\Documents\Development\Intelli-Pos\intelliPos\venv\lib\site-packages\django\core\handlers\exception.py", line 47, in inner
    response = get_response(request)
  File "C:\Users\takud\OneDrive\Documents\Development\Intelli-Pos\intelliPos\venv\lib\site-packages\django\core\handlers\base.py", line 181, in _get_response
    response = wrapped_callback(request, *callback_args, **callback_kwargs)
  File "C:\Users\takud\OneDrive\Documents\Development\Intelli-Pos\intelliPos\venv\lib\site-packages\django\views\decorators\csrf.py", line 54, in wrapped_view
    return view_func(*args, **kwargs)
  File "C:\Users\takud\OneDrive\Documents\Development\Intelli-Pos\intelliPos\venv\lib\site-packages\django\views\generic\base.py", line 70, in view
    return self.dispatch(request, *args, **kwargs)
  File "C:\Users\takud\OneDrive\Documents\Development\Intelli-Pos\intelliPos\venv\lib\site-packages\rest_framework\views.py", line 509, in dispatch
    response = self.handle_exception(exc)
  File "C:\Users\takud\OneDrive\Documents\Development\Intelli-Pos\intelliPos\venv\lib\site-packages\rest_framework\views.py", line 469, in handle_exception
    self.raise_uncaught_exception(exc)
  File "C:\Users\takud\OneDrive\Documents\Development\Intelli-Pos\intelliPos\venv\lib\site-packages\rest_framework\views.py", line 480, in raise_uncaught_exception
    raise exc
  File "C:\Users\takud\OneDrive\Documents\Development\Intelli-Pos\intelliPos\venv\lib\site-packages\rest_framework\views.py", line 506, in dispatch
    response = handler(request, *args, **kwargs)
TypeError: get() missing 1 required positional argument: 'id'
"GET /api/transactions/ HTTP/1.1" 500 94154
Not Found: /api/transactions/1
"GET /api/transactions/1 HTTP/1.1" 404 3788
Not Found: /api/transaction
"GET /api/transaction HTTP/1.1" 404 3779
Internal Server Error: /api/transactions/
Traceback (most recent call last):
  File "C:\Users\takud\OneDrive\Documents\Development\Intelli-Pos\intelliPos\venv\lib\site-packages\django\core\handlers\exception.py", line 47, in inner
    response = get_response(request)
  File "C:\Users\takud\OneDrive\Documents\Development\Intelli-Pos\intelliPos\venv\lib\site-packages\django\core\handlers\base.py", line 181, in _get_response
    response = wrapped_callback(request, *callback_args, **callback_kwargs)
  File "C:\Users\takud\OneDrive\Documents\Development\Intelli-Pos\intelliPos\venv\lib\site-packages\django\views\decorators\csrf.py", line 54, in wrapped_view
    return view_func(*args, **kwargs)
  File "C:\Users\takud\OneDrive\Documents\Development\Intelli-Pos\intelliPos\venv\lib\site-packages\django\views\generic\base.py", line 70, in view
    return self.dispatch(request, *args, **kwargs)
  File "C:\Users\takud\OneDrive\Documents\Development\Intelli-Pos\intelliPos\venv\lib\site-packages\rest_framework\views.py", line 509, in dispatch
    response = self.handle_exception(exc)
  File "C:\Users\takud\OneDrive\Documents\Development\Intelli-Pos\intelliPos\venv\lib\site-packages\rest_framework\views.py", line 469, in handle_exception
    self.raise_uncaught_exception(exc)
  File "C:\Users\takud\OneDrive\Documents\Development\Intelli-Pos\intelliPos\venv\lib\site-packages\rest_framework\views.py", line 480, in raise_uncaught_exception
    raise exc
  File "C:\Users\takud\OneDrive\Documents\Development\Intelli-Pos\intelliPos\venv\lib\site-packages\rest_framework\views.py", line 506, in dispatch
    response = handler(request, *args, **kwargs)
TypeError: get() missing 1 required positional argument: 'id'
"GET /api/transactions/ HTTP/1.1" 500 92863
Internal Server Error: /api/transactions/
Traceback (most recent call last):
  File "C:\Users\takud\OneDrive\Documents\Development\Intelli-Pos\intelliPos\venv\lib\site-packages\django\core\handlers\exception.py", line 47, in inner
    response = get_response(request)
  File "C:\Users\takud\OneDrive\Documents\Development\Intelli-Pos\intelliPos\venv\lib\site-packages\django\core\handlers\base.py", line 181, in _get_response
    response = wrapped_callback(request, *callback_args, **callback_kwargs)
  File "C:\Users\takud\OneDrive\Documents\Development\Intelli-Pos\intelliPos\venv\lib\site-packages\django\views\decorators\csrf.py", line 54, in wrapped_view
    return view_func(*args, **kwargs)
  File "C:\Users\takud\OneDrive\Documents\Development\Intelli-Pos\intelliPos\venv\lib\site-packages\django\views\generic\base.py", line 70, in view
    return self.dispatch(request, *args, **kwargs)
  File "C:\Users\takud\OneDrive\Documents\Development\Intelli-Pos\intelliPos\venv\lib\site-packages\rest_framework\views.py", line 509, in dispatch
    response = self.handle_exception(exc)
  File "C:\Users\takud\OneDrive\Documents\Development\Intelli-Pos\intelliPos\venv\lib\site-packages\rest_framework\views.py", line 469, in handle_exception
    self.raise_uncaught_exception(exc)
  File "C:\Users\takud\OneDrive\Documents\Development\Intelli-Pos\intelliPos\venv\lib\site-packages\rest_framework\views.py", line 480, in raise_uncaught_exception
    raise exc
  File "C:\Users\takud\OneDrive\Documents\Development\Intelli-Pos\intelliPos\venv\lib\site-packages\rest_framework\views.py", line 506, in dispatch
    response = handler(request, *args, **kwargs)
TypeError: get() missing 1 required positional argument: 'id'
"GET /api/transactions/?id=10 HTTP/1.1" 500 93219
Internal Server Error: /api/transactions/
Traceback (most recent call last):
  File "C:\Users\takud\OneDrive\Documents\Development\Intelli-Pos\intelliPos\venv\lib\site-packages\django\core\handlers\exception.py", line 47, in inner
    response = get_response(request)
  File "C:\Users\takud\OneDrive\Documents\Development\Intelli-Pos\intelliPos\venv\lib\site-packages\django\core\handlers\base.py", line 181, in _get_response
    response = wrapped_callback(request, *callback_args, **callback_kwargs)
  File "C:\Users\takud\OneDrive\Documents\Development\Intelli-Pos\intelliPos\venv\lib\site-packages\django\views\decorators\csrf.py", line 54, in wrapped_view
    return view_func(*args, **kwargs)
  File "C:\Users\takud\OneDrive\Documents\Development\Intelli-Pos\intelliPos\venv\lib\site-packages\django\views\generic\base.py", line 70, in view
    return self.dispatch(request, *args, **kwargs)
  File "C:\Users\takud\OneDrive\Documents\Development\Intelli-Pos\intelliPos\venv\lib\site-packages\rest_framework\views.py", line 509, in dispatch
    response = self.handle_exception(exc)
  File "C:\Users\takud\OneDrive\Documents\Development\Intelli-Pos\intelliPos\venv\lib\site-packages\rest_framework\views.py", line 469, in handle_exception
    self.raise_uncaught_exception(exc)
  File "C:\Users\takud\OneDrive\Documents\Development\Intelli-Pos\intelliPos\venv\lib\site-packages\rest_framework\views.py", line 480, in raise_uncaught_exception
    raise exc
  File "C:\Users\takud\OneDrive\Documents\Development\Intelli-Pos\intelliPos\venv\lib\site-packages\rest_framework\views.py", line 506, in dispatch
    response = handler(request, *args, **kwargs)
TypeError: get() missing 1 required positional argument: 'id'
"GET /api/transactions/?id=10 HTTP/1.1" 500 93219
Internal Server Error: /api/transactions/
Traceback (most recent call last):
  File "C:\Users\takud\OneDrive\Documents\Development\Intelli-Pos\intelliPos\venv\lib\site-packages\django\core\handlers\exception.py", line 47, in inner
    response = get_response(request)
  File "C:\Users\takud\OneDrive\Documents\Development\Intelli-Pos\intelliPos\venv\lib\site-packages\django\core\handlers\base.py", line 181, in _get_response
    response = wrapped_callback(request, *callback_args, **callback_kwargs)
  File "C:\Users\takud\OneDrive\Documents\Development\Intelli-Pos\intelliPos\venv\lib\site-packages\django\views\decorators\csrf.py", line 54, in wrapped_view
    return view_func(*args, **kwargs)
  File "C:\Users\takud\OneDrive\Documents\Development\Intelli-Pos\intelliPos\venv\lib\site-packages\django\views\generic\base.py", line 70, in view
    return self.dispatch(request, *args, **kwargs)
  File "C:\Users\takud\OneDrive\Documents\Development\Intelli-Pos\intelliPos\venv\lib\site-packages\rest_framework\views.py", line 509, in dispatch
    response = self.handle_exception(exc)
  File "C:\Users\takud\OneDrive\Documents\Development\Intelli-Pos\intelliPos\venv\lib\site-packages\rest_framework\views.py", line 469, in handle_exception
    self.raise_uncaught_exception(exc)
  File "C:\Users\takud\OneDrive\Documents\Development\Intelli-Pos\intelliPos\venv\lib\site-packages\rest_framework\views.py", line 480, in raise_uncaught_exception
    raise exc
  File "C:\Users\takud\OneDrive\Documents\Development\Intelli-Pos\intelliPos\venv\lib\site-packages\rest_framework\views.py", line 506, in dispatch
    response = handler(request, *args, **kwargs)
TypeError: get() missing 1 required positional argument: 'id'
"GET /api/transactions/?id=10 HTTP/1.1" 500 93219
Not Found: /api/transactions
"GET /api/transactions?id=10 HTTP/1.1" 404 3803
Not Found: /api/transactions/1/
"GET /api/transactions/1/ HTTP/1.1" 404 23
Not Found: /api/transactions/1/
"GET /api/transactions/1/ HTTP/1.1" 404 23
Method Not Allowed: /api/transactions/1/
"POST /api/transactions/1/ HTTP/1.1" 405 41
Internal Server Error: /api/transactions/1/
Traceback (most recent call last):
  File "C:\Users\takud\OneDrive\Documents\Development\Intelli-Pos\intelliPos\venv\lib\site-packages\django\core\handlers\exception.py", line 47, in inner
    response = get_response(request)
  File "C:\Users\takud\OneDrive\Documents\Development\Intelli-Pos\intelliPos\venv\lib\site-packages\django\core\handlers\base.py", line 181, in _get_response
    response = wrapped_callback(request, *callback_args, **callback_kwargs)
  File "C:\Users\takud\OneDrive\Documents\Development\Intelli-Pos\intelliPos\venv\lib\site-packages\django\views\decorators\csrf.py", line 54, in wrapped_view
    return view_func(*args, **kwargs)
  File "C:\Users\takud\OneDrive\Documents\Development\Intelli-Pos\intelliPos\venv\lib\site-packages\django\views\generic\base.py", line 70, in view
    return self.dispatch(request, *args, **kwargs)
  File "C:\Users\takud\OneDrive\Documents\Development\Intelli-Pos\intelliPos\venv\lib\site-packages\rest_framework\views.py", line 509, in dispatch
    response = self.handle_exception(exc)
  File "C:\Users\takud\OneDrive\Documents\Development\Intelli-Pos\intelliPos\venv\lib\site-packages\rest_framework\views.py", line 469, in handle_exception
    self.raise_uncaught_exception(exc)
  File "C:\Users\takud\OneDrive\Documents\Development\Intelli-Pos\intelliPos\venv\lib\site-packages\rest_framework\views.py", line 480, in raise_uncaught_exception
    raise exc
  File "C:\Users\takud\OneDrive\Documents\Development\Intelli-Pos\intelliPos\venv\lib\site-packages\rest_framework\views.py", line 506, in dispatch
    response = handler(request, *args, **kwargs)
TypeError: post() got an unexpected keyword argument 'id'
"POST /api/transactions/1/ HTTP/1.1" 500 93867
Internal Server Error: /api/transactions/1/
Traceback (most recent call last):
  File "C:\Users\takud\OneDrive\Documents\Development\Intelli-Pos\intelliPos\venv\lib\site-packages\django\core\handlers\exception.py", line 47, in inner
    response = get_response(request)
  File "C:\Users\takud\OneDrive\Documents\Development\Intelli-Pos\intelliPos\venv\lib\site-packages\django\core\handlers\base.py", line 181, in _get_response
    response = wrapped_callback(request, *callback_args, **callback_kwargs)
  File "C:\Users\takud\OneDrive\Documents\Development\Intelli-Pos\intelliPos\venv\lib\site-packages\django\views\decorators\csrf.py", line 54, in wrapped_view
    return view_func(*args, **kwargs)
  File "C:\Users\takud\OneDrive\Documents\Development\Intelli-Pos\intelliPos\venv\lib\site-packages\django\views\generic\base.py", line 70, in view
    return self.dispatch(request, *args, **kwargs)
  File "C:\Users\takud\OneDrive\Documents\Development\Intelli-Pos\intelliPos\venv\lib\site-packages\rest_framework\views.py", line 509, in dispatch
    response = self.handle_exception(exc)
  File "C:\Users\takud\OneDrive\Documents\Development\Intelli-Pos\intelliPos\venv\lib\site-packages\rest_framework\views.py", line 469, in handle_exception
    self.raise_uncaught_exception(exc)
  File "C:\Users\takud\OneDrive\Documents\Development\Intelli-Pos\intelliPos\venv\lib\site-packages\rest_framework\views.py", line 480, in raise_uncaught_exception
    raise exc
  File "C:\Users\takud\OneDrive\Documents\Development\Intelli-Pos\intelliPos\venv\lib\site-packages\rest_framework\views.py", line 506, in dispatch
    response = handler(request, *args, **kwargs)
TypeError: post() got an unexpected keyword argument 'id'
"POST /api/transactions/1/ HTTP/1.1" 500 94184
Internal Server Error: /api/transactions/1/
Traceback (most recent call last):
  File "C:\Users\takud\OneDrive\Documents\Development\Intelli-Pos\intelliPos\venv\lib\site-packages\django\core\handlers\exception.py", line 47, in inner
    response = get_response(request)
  File "C:\Users\takud\OneDrive\Documents\Development\Intelli-Pos\intelliPos\venv\lib\site-packages\django\core\handlers\base.py", line 181, in _get_response
    response = wrapped_callback(request, *callback_args, **callback_kwargs)
  File "C:\Users\takud\OneDrive\Documents\Development\Intelli-Pos\intelliPos\venv\lib\site-packages\django\views\decorators\csrf.py", line 54, in wrapped_view
    return view_func(*args, **kwargs)
  File "C:\Users\takud\OneDrive\Documents\Development\Intelli-Pos\intelliPos\venv\lib\site-packages\django\views\generic\base.py", line 70, in view
    return self.dispatch(request, *args, **kwargs)
  File "C:\Users\takud\OneDrive\Documents\Development\Intelli-Pos\intelliPos\venv\lib\site-packages\rest_framework\views.py", line 509, in dispatch
    response = self.handle_exception(exc)
  File "C:\Users\takud\OneDrive\Documents\Development\Intelli-Pos\intelliPos\venv\lib\site-packages\rest_framework\views.py", line 469, in handle_exception
    self.raise_uncaught_exception(exc)
  File "C:\Users\takud\OneDrive\Documents\Development\Intelli-Pos\intelliPos\venv\lib\site-packages\rest_framework\views.py", line 480, in raise_uncaught_exception
    raise exc
  File "C:\Users\takud\OneDrive\Documents\Development\Intelli-Pos\intelliPos\venv\lib\site-packages\rest_framework\views.py", line 506, in dispatch
    response = handler(request, *args, **kwargs)
TypeError: post() got an unexpected keyword argument 'id'
"POST /api/transactions/1/ HTTP/1.1" 500 93920
Not Found: /api/transactions
"POST /api/transactions HTTP/1.1" 404 3798
Not Found: /api/transactions/1/
"POST /api/transactions/1/ HTTP/1.1" 404 23
Unauthorized: /api/transactions/1/
"POST /api/transactions/1/ HTTP/1.1" 401 183
Internal Server Error: /api/token
Traceback (most recent call last):
  File "C:\Users\takud\OneDrive\Documents\Development\Intelli-Pos\intelliPos\venv\lib\site-packages\django\core\handlers\exception.py", line 47, in inner
    response = get_response(request)
  File "C:\Users\takud\OneDrive\Documents\Development\Intelli-Pos\intelliPos\venv\lib\site-packages\django\utils\deprecation.py", line 113, in __call__
    response = self.process_request(request)
  File "C:\Users\takud\OneDrive\Documents\Development\Intelli-Pos\intelliPos\venv\lib\site-packages\django\middleware\common.py", line 54, in process_request
    path = self.get_full_path_with_slash(request)
  File "C:\Users\takud\OneDrive\Documents\Development\Intelli-Pos\intelliPos\venv\lib\site-packages\django\middleware\common.py", line 94, in get_full_path_with_slash
    'url': request.get_host() + new_path,
RuntimeError: You called this URL via POST, but the URL doesn't end in a slash and you have APPEND_SLASH set. Django can't redirect to the slash URL while maintaining POST data. Change your form to point to 127.0.0.1:8000/api/token/ (note the trailing slash), or set APPEND_SLASH=False in your Django settings.
"POST /api/token HTTP/1.1" 500 76314
Bad Request: /api/token/
"POST /api/token/ HTTP/1.1" 400 79
Unauthorized: /api/token/
"POST /api/token/ HTTP/1.1" 401 63
Not Found: /api/transactions
"GET /api/transactions?id=10 HTTP/1.1" 404 4173
Unauthorized: /api/transactions/1/
"GET /api/transactions/1/ HTTP/1.1" 401 183
Not Found: /api/transactions/1/
"GET /api/transactions/1/ HTTP/1.1" 404 23
Unauthorized: /api/transactions/1/
"POST /api/transactions/1/ HTTP/1.1" 401 183
Unauthorized: /api/transactions/1/
"GET /api/transactions/1/ HTTP/1.1" 401 183
Unauthorized: /api/transactions/1/
"POST /api/transactions/1/ HTTP/1.1" 401 183
Not Found: /api/transactions/1/
"POST /api/transactions/1/ HTTP/1.1" 404 23
Internal Server Error: /api/transactions/1/
Traceback (most recent call last):
  File "C:\Users\takud\OneDrive\Documents\Development\Intelli-Pos\intelliPos\venv\lib\site-packages\django\core\handlers\exception.py", line 47, in inner
    response = get_response(request)
  File "C:\Users\takud\OneDrive\Documents\Development\Intelli-Pos\intelliPos\venv\lib\site-packages\django\core\handlers\base.py", line 181, in _get_response
    response = wrapped_callback(request, *callback_args, **callback_kwargs)
  File "C:\Users\takud\OneDrive\Documents\Development\Intelli-Pos\intelliPos\venv\lib\site-packages\django\views\decorators\csrf.py", line 54, in wrapped_view
    return view_func(*args, **kwargs)
  File "C:\Users\takud\OneDrive\Documents\Development\Intelli-Pos\intelliPos\venv\lib\site-packages\django\views\generic\base.py", line 70, in view
    return self.dispatch(request, *args, **kwargs)
  File "C:\Users\takud\OneDrive\Documents\Development\Intelli-Pos\intelliPos\venv\lib\site-packages\rest_framework\views.py", line 509, in dispatch
    response = self.handle_exception(exc)
  File "C:\Users\takud\OneDrive\Documents\Development\Intelli-Pos\intelliPos\venv\lib\site-packages\rest_framework\views.py", line 469, in handle_exception
    self.raise_uncaught_exception(exc)
  File "C:\Users\takud\OneDrive\Documents\Development\Intelli-Pos\intelliPos\venv\lib\site-packages\rest_framework\views.py", line 480, in raise_uncaught_exception
    raise exc
  File "C:\Users\takud\OneDrive\Documents\Development\Intelli-Pos\intelliPos\venv\lib\site-packages\rest_framework\views.py", line 506, in dispatch
    response = handler(request, *args, **kwargs)
  File "C:\Users\takud\OneDrive\Documents\Development\Intelli-Pos\intelliPos\api\views.py", line 49, in get
    print(r.json())
  File "C:\Users\takud\OneDrive\Documents\Development\Intelli-Pos\intelliPos\venv\lib\site-packages\requests\models.py", line 900, in json
    return complexjson.loads(self.text, **kwargs)
  File "c:\users\takud\appdata\local\programs\python\python37\lib\json\__init__.py", line 348, in loads
    return _default_decoder.decode(s)
  File "c:\users\takud\appdata\local\programs\python\python37\lib\json\decoder.py", line 337, in decode
    obj, end = self.raw_decode(s, idx=_w(s, 0).end())
  File "c:\users\takud\appdata\local\programs\python\python37\lib\json\decoder.py", line 355, in raw_decode
    raise JSONDecodeError("Expecting value", s, err.value) from None
json.decoder.JSONDecodeError: Expecting value: line 1 column 1 (char 0)
"GET /api/transactions/1/ HTTP/1.1" 500 119210
Not Found: /api/transactions/1/
"GET /api/transactions/1/ HTTP/1.1" 404 23
Not Found: /api/transactions/1/
"GET /api/transactions/1/ HTTP/1.1" 404 23
Internal Server Error: /api/transactions/1/
Traceback (most recent call last):
  File "C:\Users\takud\OneDrive\Documents\Development\Intelli-Pos\intelliPos\venv\lib\site-packages\django\core\handlers\exception.py", line 47, in inner
    response = get_response(request)
  File "C:\Users\takud\OneDrive\Documents\Development\Intelli-Pos\intelliPos\venv\lib\site-packages\django\core\handlers\base.py", line 181, in _get_response
    response = wrapped_callback(request, *callback_args, **callback_kwargs)
  File "C:\Users\takud\OneDrive\Documents\Development\Intelli-Pos\intelliPos\venv\lib\site-packages\django\views\decorators\csrf.py", line 54, in wrapped_view
    return view_func(*args, **kwargs)
  File "C:\Users\takud\OneDrive\Documents\Development\Intelli-Pos\intelliPos\venv\lib\site-packages\django\views\generic\base.py", line 70, in view
    return self.dispatch(request, *args, **kwargs)
  File "C:\Users\takud\OneDrive\Documents\Development\Intelli-Pos\intelliPos\venv\lib\site-packages\rest_framework\views.py", line 509, in dispatch
    response = self.handle_exception(exc)
  File "C:\Users\takud\OneDrive\Documents\Development\Intelli-Pos\intelliPos\venv\lib\site-packages\rest_framework\views.py", line 469, in handle_exception
    self.raise_uncaught_exception(exc)
  File "C:\Users\takud\OneDrive\Documents\Development\Intelli-Pos\intelliPos\venv\lib\site-packages\rest_framework\views.py", line 480, in raise_uncaught_exception
    raise exc
  File "C:\Users\takud\OneDrive\Documents\Development\Intelli-Pos\intelliPos\venv\lib\site-packages\rest_framework\views.py", line 506, in dispatch
    response = handler(request, *args, **kwargs)
  File "C:\Users\takud\OneDrive\Documents\Development\Intelli-Pos\intelliPos\api\views.py", line 47, in get
    access_token = access_token('intellipos')
UnboundLocalError: local variable 'access_token' referenced before assignment
"GET /api/transactions/1/ HTTP/1.1" 500 97650
Unauthorized: /api/transactions/1/
"GET /api/transactions/1/ HTTP/1.1" 401 183
Internal Server Error: /api/transactions/1/
Traceback (most recent call last):
  File "C:\Users\takud\OneDrive\Documents\Development\Intelli-Pos\intelliPos\venv\lib\site-packages\django\core\handlers\exception.py", line 47, in inner
    response = get_response(request)
  File "C:\Users\takud\OneDrive\Documents\Development\Intelli-Pos\intelliPos\venv\lib\site-packages\django\core\handlers\base.py", line 181, in _get_response
    response = wrapped_callback(request, *callback_args, **callback_kwargs)
  File "C:\Users\takud\OneDrive\Documents\Development\Intelli-Pos\intelliPos\venv\lib\site-packages\django\views\decorators\csrf.py", line 54, in wrapped_view
    return view_func(*args, **kwargs)
  File "C:\Users\takud\OneDrive\Documents\Development\Intelli-Pos\intelliPos\venv\lib\site-packages\django\views\generic\base.py", line 70, in view
    return self.dispatch(request, *args, **kwargs)
  File "C:\Users\takud\OneDrive\Documents\Development\Intelli-Pos\intelliPos\venv\lib\site-packages\rest_framework\views.py", line 509, in dispatch
    response = self.handle_exception(exc)
  File "C:\Users\takud\OneDrive\Documents\Development\Intelli-Pos\intelliPos\venv\lib\site-packages\rest_framework\views.py", line 469, in handle_exception
    self.raise_uncaught_exception(exc)
  File "C:\Users\takud\OneDrive\Documents\Development\Intelli-Pos\intelliPos\venv\lib\site-packages\rest_framework\views.py", line 480, in raise_uncaught_exception
    raise exc
  File "C:\Users\takud\OneDrive\Documents\Development\Intelli-Pos\intelliPos\venv\lib\site-packages\rest_framework\views.py", line 506, in dispatch
    response = handler(request, *args, **kwargs)
  File "C:\Users\takud\OneDrive\Documents\Development\Intelli-Pos\intelliPos\api\views.py", line 47, in get
    access_token = access_token('intellipos')
UnboundLocalError: local variable 'access_token' referenced before assignment
"GET /api/transactions/1/ HTTP/1.1" 500 97650
Not Found: /api/transactions/1/
"GET /api/transactions/1/ HTTP/1.1" 404 23
Method Not Allowed: /api/token/
"GET /api/token/ HTTP/1.1" 405 40
Internal Server Error: /api/token
Traceback (most recent call last):
  File "C:\Users\takud\OneDrive\Documents\Development\Intelli-Pos\intelliPos\venv\lib\site-packages\django\core\handlers\exception.py", line 47, in inner
    response = get_response(request)
  File "C:\Users\takud\OneDrive\Documents\Development\Intelli-Pos\intelliPos\venv\lib\site-packages\django\utils\deprecation.py", line 113, in __call__
    response = self.process_request(request)
  File "C:\Users\takud\OneDrive\Documents\Development\Intelli-Pos\intelliPos\venv\lib\site-packages\django\middleware\common.py", line 54, in process_request
    path = self.get_full_path_with_slash(request)
  File "C:\Users\takud\OneDrive\Documents\Development\Intelli-Pos\intelliPos\venv\lib\site-packages\django\middleware\common.py", line 94, in get_full_path_with_slash
    'url': request.get_host() + new_path,
RuntimeError: You called this URL via POST, but the URL doesn't end in a slash and you have APPEND_SLASH set. Django can't redirect to the slash URL while maintaining POST data. Change your form to point to 127.0.0.1:8000/api/token/ (note the trailing slash), or set APPEND_SLASH=False in your Django settings.
"POST /api/token HTTP/1.1" 500 74668
Bad Request: /api/token/
"POST /api/token/ HTTP/1.1" 400 79
Bad Request: /api/token/
"POST /api/token/?username=timothy&password=12345 HTTP/1.1" 400 79
Unauthorized: /api/token/
"POST /api/token/?username=timothy&password=12345 HTTP/1.1" 401 63
Not Found: /favicon.ico
"GET /favicon.ico HTTP/1.1" 404 2080
Not Found: /api/token/
"POST /api/token/?username=timothy&password=12345 HTTP/1.1" 404 4190
Unauthorized: /api/transactions/1/
"GET /api/transactions/1/ HTTP/1.1" 401 58
Unauthorized: /api/transactions/1/
"GET /api/transactions/1/ HTTP/1.1" 401 183
Unauthorized: /api/transactions/1/
"GET /api/transactions/1/ HTTP/1.1" 401 58
Unauthorized: /api/transactions/1/
"GET /api/transactions/1/ HTTP/1.1" 401 183
Internal Server Error: /api/transactions/1/
Traceback (most recent call last):
  File "C:\Users\takud\OneDrive\Documents\Development\Intelli-Pos\intelliPos\venv\lib\site-packages\urllib3\connection.py", line 170, in _new_conn
    (self._dns_host, self.port), self.timeout, **extra_kw
  File "C:\Users\takud\OneDrive\Documents\Development\Intelli-Pos\intelliPos\venv\lib\site-packages\urllib3\util\connection.py", line 96, in create_connection
    raise err
  File "C:\Users\takud\OneDrive\Documents\Development\Intelli-Pos\intelliPos\venv\lib\site-packages\urllib3\util\connection.py", line 86, in create_connection
    sock.connect(sa)
ConnectionRefusedError: [WinError 10061] No connection could be made because the target machine actively refused it

During handling of the above exception, another exception occurred:

Traceback (most recent call last):
  File "C:\Users\takud\OneDrive\Documents\Development\Intelli-Pos\intelliPos\venv\lib\site-packages\urllib3\connectionpool.py", line 706, in urlopen
    chunked=chunked,
  File "C:\Users\takud\OneDrive\Documents\Development\Intelli-Pos\intelliPos\venv\lib\site-packages\urllib3\connectionpool.py", line 394, in _make_request
    conn.request(method, url, **httplib_request_kw)
  File "C:\Users\takud\OneDrive\Documents\Development\Intelli-Pos\intelliPos\venv\lib\site-packages\urllib3\connection.py", line 234, in request
    super(HTTPConnection, self).request(method, url, body=body, headers=headers)
  File "c:\users\takud\appdata\local\programs\python\python37\lib\http\client.py", line 1244, in request
    self._send_request(method, url, body, headers, encode_chunked)
  File "c:\users\takud\appdata\local\programs\python\python37\lib\http\client.py", line 1290, in _send_request
    self.endheaders(body, encode_chunked=encode_chunked)
  File "c:\users\takud\appdata\local\programs\python\python37\lib\http\client.py", line 1239, in endheaders
    self._send_output(message_body, encode_chunked=encode_chunked)
  File "c:\users\takud\appdata\local\programs\python\python37\lib\http\client.py", line 1026, in _send_output
    self.send(msg)
  File "c:\users\takud\appdata\local\programs\python\python37\lib\http\client.py", line 966, in send
    self.connect()
  File "C:\Users\takud\OneDrive\Documents\Development\Intelli-Pos\intelliPos\venv\lib\site-packages\urllib3\connection.py", line 200, in connect
    conn = self._new_conn()
  File "C:\Users\takud\OneDrive\Documents\Development\Intelli-Pos\intelliPos\venv\lib\site-packages\urllib3\connection.py", line 182, in _new_conn
    self, "Failed to establish a new connection: %s" % e
urllib3.exceptions.NewConnectionError: <urllib3.connection.HTTPConnection object at 0x0000025F8D5A5308>: Failed to establish a new connection: [WinError 10061] No connection could be made because the target machine actively refused it

During handling of the above exception, another exception occurred:

Traceback (most recent call last):
  File "C:\Users\takud\OneDrive\Documents\Development\Intelli-Pos\intelliPos\venv\lib\site-packages\requests\adapters.py", line 449, in send
    timeout=timeout
  File "C:\Users\takud\OneDrive\Documents\Development\Intelli-Pos\intelliPos\venv\lib\site-packages\urllib3\connectionpool.py", line 756, in urlopen
    method, url, error=e, _pool=self, _stacktrace=sys.exc_info()[2]
  File "C:\Users\takud\OneDrive\Documents\Development\Intelli-Pos\intelliPos\venv\lib\site-packages\urllib3\util\retry.py", line 573, in increment
    raise MaxRetryError(_pool, url, error or ResponseError(cause))
urllib3.exceptions.MaxRetryError: HTTPConnectionPool(host='45.55.44.41', port=8003): Max retries exceeded with url: /api/v1/keys (Caused by NewConnectionError('<urllib3.connection.HTTPConnection object at 0x0000025F8D5A5308>: Failed to establish a new connection: [WinError 10061] No connection could be made because the target machine actively refused it'))

During handling of the above exception, another exception occurred:

Traceback (most recent call last):
  File "C:\Users\takud\OneDrive\Documents\Development\Intelli-Pos\intelliPos\venv\lib\site-packages\django\core\handlers\exception.py", line 47, in inner
    response = get_response(request)
  File "C:\Users\takud\OneDrive\Documents\Development\Intelli-Pos\intelliPos\venv\lib\site-packages\django\core\handlers\base.py", line 181, in _get_response
    response = wrapped_callback(request, *callback_args, **callback_kwargs)
  File "C:\Users\takud\OneDrive\Documents\Development\Intelli-Pos\intelliPos\venv\lib\site-packages\django\views\decorators\csrf.py", line 54, in wrapped_view
    return view_func(*args, **kwargs)
  File "C:\Users\takud\OneDrive\Documents\Development\Intelli-Pos\intelliPos\venv\lib\site-packages\django\views\generic\base.py", line 70, in view
    return self.dispatch(request, *args, **kwargs)
  File "C:\Users\takud\OneDrive\Documents\Development\Intelli-Pos\intelliPos\venv\lib\site-packages\rest_framework\views.py", line 509, in dispatch
    response = self.handle_exception(exc)
  File "C:\Users\takud\OneDrive\Documents\Development\Intelli-Pos\intelliPos\venv\lib\site-packages\rest_framework\views.py", line 469, in handle_exception
    self.raise_uncaught_exception(exc)
  File "C:\Users\takud\OneDrive\Documents\Development\Intelli-Pos\intelliPos\venv\lib\site-packages\rest_framework\views.py", line 480, in raise_uncaught_exception
    raise exc
  File "C:\Users\takud\OneDrive\Documents\Development\Intelli-Pos\intelliPos\venv\lib\site-packages\rest_framework\views.py", line 506, in dispatch
    response = handler(request, *args, **kwargs)
  File "C:\Users\takud\OneDrive\Documents\Development\Intelli-Pos\intelliPos\api\views.py", line 57, in get
    r = requests.get(url, headers=headers)
  File "C:\Users\takud\OneDrive\Documents\Development\Intelli-Pos\intelliPos\venv\lib\site-packages\requests\api.py", line 76, in get
    return request('get', url, params=params, **kwargs)
  File "C:\Users\takud\OneDrive\Documents\Development\Intelli-Pos\intelliPos\venv\lib\site-packages\requests\api.py", line 61, in request
    return session.request(method=method, url=url, **kwargs)
  File "C:\Users\takud\OneDrive\Documents\Development\Intelli-Pos\intelliPos\venv\lib\site-packages\requests\sessions.py", line 542, in request
    resp = self.send(prep, **send_kwargs)
  File "C:\Users\takud\OneDrive\Documents\Development\Intelli-Pos\intelliPos\venv\lib\site-packages\requests\sessions.py", line 655, in send
    r = adapter.send(request, **kwargs)
  File "C:\Users\takud\OneDrive\Documents\Development\Intelli-Pos\intelliPos\venv\lib\site-packages\requests\adapters.py", line 516, in send
    raise ConnectionError(e, request=request)
requests.exceptions.ConnectionError: HTTPConnectionPool(host='45.55.44.41', port=8003): Max retries exceeded with url: /api/v1/keys (Caused by NewConnectionError('<urllib3.connection.HTTPConnection object at 0x0000025F8D5A5308>: Failed to establish a new connection: [WinError 10061] No connection could be made because the target machine actively refused it'))
"GET /api/transactions/1/ HTTP/1.1" 500 219270
Internal Server Error: /api/transactions/1/
Traceback (most recent call last):
  File "C:\Users\takud\OneDrive\Documents\Development\Intelli-Pos\intelliPos\venv\lib\site-packages\urllib3\connection.py", line 170, in _new_conn
    (self._dns_host, self.port), self.timeout, **extra_kw
  File "C:\Users\takud\OneDrive\Documents\Development\Intelli-Pos\intelliPos\venv\lib\site-packages\urllib3\util\connection.py", line 96, in create_connection
    raise err
  File "C:\Users\takud\OneDrive\Documents\Development\Intelli-Pos\intelliPos\venv\lib\site-packages\urllib3\util\connection.py", line 86, in create_connection
    sock.connect(sa)
ConnectionRefusedError: [WinError 10061] No connection could be made because the target machine actively refused it

During handling of the above exception, another exception occurred:

Traceback (most recent call last):
  File "C:\Users\takud\OneDrive\Documents\Development\Intelli-Pos\intelliPos\venv\lib\site-packages\urllib3\connectionpool.py", line 706, in urlopen
    chunked=chunked,
  File "C:\Users\takud\OneDrive\Documents\Development\Intelli-Pos\intelliPos\venv\lib\site-packages\urllib3\connectionpool.py", line 394, in _make_request
    conn.request(method, url, **httplib_request_kw)
  File "C:\Users\takud\OneDrive\Documents\Development\Intelli-Pos\intelliPos\venv\lib\site-packages\urllib3\connection.py", line 234, in request
    super(HTTPConnection, self).request(method, url, body=body, headers=headers)
  File "c:\users\takud\appdata\local\programs\python\python37\lib\http\client.py", line 1244, in request
    self._send_request(method, url, body, headers, encode_chunked)
  File "c:\users\takud\appdata\local\programs\python\python37\lib\http\client.py", line 1290, in _send_request
    self.endheaders(body, encode_chunked=encode_chunked)
  File "c:\users\takud\appdata\local\programs\python\python37\lib\http\client.py", line 1239, in endheaders
    self._send_output(message_body, encode_chunked=encode_chunked)
  File "c:\users\takud\appdata\local\programs\python\python37\lib\http\client.py", line 1026, in _send_output
    self.send(msg)
  File "c:\users\takud\appdata\local\programs\python\python37\lib\http\client.py", line 966, in send
    self.connect()
  File "C:\Users\takud\OneDrive\Documents\Development\Intelli-Pos\intelliPos\venv\lib\site-packages\urllib3\connection.py", line 200, in connect
    conn = self._new_conn()
  File "C:\Users\takud\OneDrive\Documents\Development\Intelli-Pos\intelliPos\venv\lib\site-packages\urllib3\connection.py", line 182, in _new_conn
    self, "Failed to establish a new connection: %s" % e
urllib3.exceptions.NewConnectionError: <urllib3.connection.HTTPConnection object at 0x0000025F8D527288>: Failed to establish a new connection: [WinError 10061] No connection could be made because the target machine actively refused it

During handling of the above exception, another exception occurred:

Traceback (most recent call last):
  File "C:\Users\takud\OneDrive\Documents\Development\Intelli-Pos\intelliPos\venv\lib\site-packages\requests\adapters.py", line 449, in send
    timeout=timeout
  File "C:\Users\takud\OneDrive\Documents\Development\Intelli-Pos\intelliPos\venv\lib\site-packages\urllib3\connectionpool.py", line 756, in urlopen
    method, url, error=e, _pool=self, _stacktrace=sys.exc_info()[2]
  File "C:\Users\takud\OneDrive\Documents\Development\Intelli-Pos\intelliPos\venv\lib\site-packages\urllib3\util\retry.py", line 573, in increment
    raise MaxRetryError(_pool, url, error or ResponseError(cause))
urllib3.exceptions.MaxRetryError: HTTPConnectionPool(host='45.55.44.41', port=8003): Max retries exceeded with url: /api/v1/keys (Caused by NewConnectionError('<urllib3.connection.HTTPConnection object at 0x0000025F8D527288>: Failed to establish a new connection: [WinError 10061] No connection could be made because the target machine actively refused it'))

During handling of the above exception, another exception occurred:

Traceback (most recent call last):
  File "C:\Users\takud\OneDrive\Documents\Development\Intelli-Pos\intelliPos\venv\lib\site-packages\django\core\handlers\exception.py", line 47, in inner
    response = get_response(request)
  File "C:\Users\takud\OneDrive\Documents\Development\Intelli-Pos\intelliPos\venv\lib\site-packages\django\core\handlers\base.py", line 181, in _get_response
    response = wrapped_callback(request, *callback_args, **callback_kwargs)
  File "C:\Users\takud\OneDrive\Documents\Development\Intelli-Pos\intelliPos\venv\lib\site-packages\django\views\decorators\csrf.py", line 54, in wrapped_view
    return view_func(*args, **kwargs)
  File "C:\Users\takud\OneDrive\Documents\Development\Intelli-Pos\intelliPos\venv\lib\site-packages\django\views\generic\base.py", line 70, in view
    return self.dispatch(request, *args, **kwargs)
  File "C:\Users\takud\OneDrive\Documents\Development\Intelli-Pos\intelliPos\venv\lib\site-packages\rest_framework\views.py", line 509, in dispatch
    response = self.handle_exception(exc)
  File "C:\Users\takud\OneDrive\Documents\Development\Intelli-Pos\intelliPos\venv\lib\site-packages\rest_framework\views.py", line 469, in handle_exception
    self.raise_uncaught_exception(exc)
  File "C:\Users\takud\OneDrive\Documents\Development\Intelli-Pos\intelliPos\venv\lib\site-packages\rest_framework\views.py", line 480, in raise_uncaught_exception
    raise exc
  File "C:\Users\takud\OneDrive\Documents\Development\Intelli-Pos\intelliPos\venv\lib\site-packages\rest_framework\views.py", line 506, in dispatch
    response = handler(request, *args, **kwargs)
  File "C:\Users\takud\OneDrive\Documents\Development\Intelli-Pos\intelliPos\api\views.py", line 57, in get
    r = requests.get(url, headers=headers)
  File "C:\Users\takud\OneDrive\Documents\Development\Intelli-Pos\intelliPos\venv\lib\site-packages\requests\api.py", line 76, in get
    return request('get', url, params=params, **kwargs)
  File "C:\Users\takud\OneDrive\Documents\Development\Intelli-Pos\intelliPos\venv\lib\site-packages\requests\api.py", line 61, in request
    return session.request(method=method, url=url, **kwargs)
  File "C:\Users\takud\OneDrive\Documents\Development\Intelli-Pos\intelliPos\venv\lib\site-packages\requests\sessions.py", line 542, in request
    resp = self.send(prep, **send_kwargs)
  File "C:\Users\takud\OneDrive\Documents\Development\Intelli-Pos\intelliPos\venv\lib\site-packages\requests\sessions.py", line 655, in send
    r = adapter.send(request, **kwargs)
  File "C:\Users\takud\OneDrive\Documents\Development\Intelli-Pos\intelliPos\venv\lib\site-packages\requests\adapters.py", line 516, in send
    raise ConnectionError(e, request=request)
requests.exceptions.ConnectionError: HTTPConnectionPool(host='45.55.44.41', port=8003): Max retries exceeded with url: /api/v1/keys (Caused by NewConnectionError('<urllib3.connection.HTTPConnection object at 0x0000025F8D527288>: Failed to establish a new connection: [WinError 10061] No connection could be made because the target machine actively refused it'))
"GET /api/transactions/1/ HTTP/1.1" 500 219271
Unauthorized: /api/transactions/1/
"GET /api/transactions/1/ HTTP/1.1" 401 58
Unauthorized: /api/transactions/1/
"GET /api/transactions/1/ HTTP/1.1" 401 58
Unauthorized: /api/transactions/1/
"GET /api/transactions/1/ HTTP/1.1" 401 58
Not Found: /api/transactions/1/
"GET /api/transactions/1/ HTTP/1.1" 404 23
Unauthorized: /api/login/
"GET /api/login/ HTTP/1.1" 401 183
Unauthorized: /api/login/
"GET /api/login/ HTTP/1.1" 401 183
Unauthorized: /api/transactions/1/
"GET /api/transactions/1/ HTTP/1.1" 401 58
Method Not Allowed: /api/login/
"GET /api/login/ HTTP/1.1" 405 40
Internal Server Error: /api/login
Traceback (most recent call last):
  File "C:\Users\takud\OneDrive\Documents\Development\Intelli-Pos\intelliPos\venv\lib\site-packages\django\core\handlers\exception.py", line 47, in inner
    response = get_response(request)
  File "C:\Users\takud\OneDrive\Documents\Development\Intelli-Pos\intelliPos\venv\lib\site-packages\django\utils\deprecation.py", line 113, in __call__
    response = self.process_request(request)
  File "C:\Users\takud\OneDrive\Documents\Development\Intelli-Pos\intelliPos\venv\lib\site-packages\django\middleware\common.py", line 54, in process_request
    path = self.get_full_path_with_slash(request)
  File "C:\Users\takud\OneDrive\Documents\Development\Intelli-Pos\intelliPos\venv\lib\site-packages\django\middleware\common.py", line 94, in get_full_path_with_slash
    'url': request.get_host() + new_path,
RuntimeError: You called this URL via POST, but the URL doesn't end in a slash and you have APPEND_SLASH set. Django can't redirect to the slash URL while maintaining POST data. Change your form to point to 127.0.0.1:8000/api/login/ (note the trailing slash), or set APPEND_SLASH=False in your Django settings.
"POST /api/login HTTP/1.1" 500 75489
Internal Server Error: /api/login/
"POST /api/login/ HTTP/1.1" 500 30
Internal Server Error: /api/login/
Traceback (most recent call last):
  File "C:\Users\takud\OneDrive\Documents\Development\Intelli-Pos\intelliPos\venv\lib\site-packages\django\core\handlers\exception.py", line 47, in inner
    response = get_response(request)
  File "C:\Users\takud\OneDrive\Documents\Development\Intelli-Pos\intelliPos\venv\lib\site-packages\django\core\handlers\base.py", line 181, in _get_response
    response = wrapped_callback(request, *callback_args, **callback_kwargs)
  File "C:\Users\takud\OneDrive\Documents\Development\Intelli-Pos\intelliPos\venv\lib\site-packages\django\views\decorators\csrf.py", line 54, in wrapped_view
    return view_func(*args, **kwargs)
  File "C:\Users\takud\OneDrive\Documents\Development\Intelli-Pos\intelliPos\venv\lib\site-packages\django\views\generic\base.py", line 70, in view
    return self.dispatch(request, *args, **kwargs)
  File "C:\Users\takud\OneDrive\Documents\Development\Intelli-Pos\intelliPos\venv\lib\site-packages\rest_framework\views.py", line 509, in dispatch
    response = self.handle_exception(exc)
  File "C:\Users\takud\OneDrive\Documents\Development\Intelli-Pos\intelliPos\venv\lib\site-packages\rest_framework\views.py", line 469, in handle_exception
    self.raise_uncaught_exception(exc)
  File "C:\Users\takud\OneDrive\Documents\Development\Intelli-Pos\intelliPos\venv\lib\site-packages\rest_framework\views.py", line 480, in raise_uncaught_exception
    raise exc
  File "C:\Users\takud\OneDrive\Documents\Development\Intelli-Pos\intelliPos\venv\lib\site-packages\rest_framework\views.py", line 506, in dispatch
    response = handler(request, *args, **kwargs)
  File "C:\Users\takud\OneDrive\Documents\Development\Intelli-Pos\intelliPos\api\views.py", line 47, in post
    username = data['username']
KeyError: 'username'
"POST /api/login/ HTTP/1.1" 500 96719
Internal Server Error: /api/login/
Traceback (most recent call last):
  File "C:\Users\takud\OneDrive\Documents\Development\Intelli-Pos\intelliPos\venv\lib\site-packages\django\utils\datastructures.py", line 76, in __getitem__
    list_ = super().__getitem__(key)
KeyError: 'password'

During handling of the above exception, another exception occurred:

Traceback (most recent call last):
  File "C:\Users\takud\OneDrive\Documents\Development\Intelli-Pos\intelliPos\venv\lib\site-packages\django\core\handlers\exception.py", line 47, in inner
    response = get_response(request)
  File "C:\Users\takud\OneDrive\Documents\Development\Intelli-Pos\intelliPos\venv\lib\site-packages\django\core\handlers\base.py", line 181, in _get_response
    response = wrapped_callback(request, *callback_args, **callback_kwargs)
  File "C:\Users\takud\OneDrive\Documents\Development\Intelli-Pos\intelliPos\venv\lib\site-packages\django\views\decorators\csrf.py", line 54, in wrapped_view
    return view_func(*args, **kwargs)
  File "C:\Users\takud\OneDrive\Documents\Development\Intelli-Pos\intelliPos\venv\lib\site-packages\django\views\generic\base.py", line 70, in view
    return self.dispatch(request, *args, **kwargs)
  File "C:\Users\takud\OneDrive\Documents\Development\Intelli-Pos\intelliPos\venv\lib\site-packages\rest_framework\views.py", line 509, in dispatch
    response = self.handle_exception(exc)
  File "C:\Users\takud\OneDrive\Documents\Development\Intelli-Pos\intelliPos\venv\lib\site-packages\rest_framework\views.py", line 469, in handle_exception
    self.raise_uncaught_exception(exc)
  File "C:\Users\takud\OneDrive\Documents\Development\Intelli-Pos\intelliPos\venv\lib\site-packages\rest_framework\views.py", line 480, in raise_uncaught_exception
    raise exc
  File "C:\Users\takud\OneDrive\Documents\Development\Intelli-Pos\intelliPos\venv\lib\site-packages\rest_framework\views.py", line 506, in dispatch
    response = handler(request, *args, **kwargs)
  File "C:\Users\takud\OneDrive\Documents\Development\Intelli-Pos\intelliPos\api\views.py", line 48, in post
    password = data['password']
  File "C:\Users\takud\OneDrive\Documents\Development\Intelli-Pos\intelliPos\venv\lib\site-packages\django\utils\datastructures.py", line 78, in __getitem__
    raise MultiValueDictKeyError(key)
django.utils.datastructures.MultiValueDictKeyError: 'password'
"POST /api/login/ HTTP/1.1" 500 105953
Internal Server Error: /api/login/
Traceback (most recent call last):
  File "C:\Users\takud\OneDrive\Documents\Development\Intelli-Pos\intelliPos\venv\lib\site-packages\django\utils\datastructures.py", line 76, in __getitem__
    list_ = super().__getitem__(key)
KeyError: 'posID'

During handling of the above exception, another exception occurred:

Traceback (most recent call last):
  File "C:\Users\takud\OneDrive\Documents\Development\Intelli-Pos\intelliPos\venv\lib\site-packages\django\core\handlers\exception.py", line 47, in inner
    response = get_response(request)
  File "C:\Users\takud\OneDrive\Documents\Development\Intelli-Pos\intelliPos\venv\lib\site-packages\django\core\handlers\base.py", line 181, in _get_response
    response = wrapped_callback(request, *callback_args, **callback_kwargs)
  File "C:\Users\takud\OneDrive\Documents\Development\Intelli-Pos\intelliPos\venv\lib\site-packages\django\views\decorators\csrf.py", line 54, in wrapped_view
    return view_func(*args, **kwargs)
  File "C:\Users\takud\OneDrive\Documents\Development\Intelli-Pos\intelliPos\venv\lib\site-packages\django\views\generic\base.py", line 70, in view
    return self.dispatch(request, *args, **kwargs)
  File "C:\Users\takud\OneDrive\Documents\Development\Intelli-Pos\intelliPos\venv\lib\site-packages\rest_framework\views.py", line 509, in dispatch
    response = self.handle_exception(exc)
  File "C:\Users\takud\OneDrive\Documents\Development\Intelli-Pos\intelliPos\venv\lib\site-packages\rest_framework\views.py", line 469, in handle_exception
    self.raise_uncaught_exception(exc)
  File "C:\Users\takud\OneDrive\Documents\Development\Intelli-Pos\intelliPos\venv\lib\site-packages\rest_framework\views.py", line 480, in raise_uncaught_exception
    raise exc
  File "C:\Users\takud\OneDrive\Documents\Development\Intelli-Pos\intelliPos\venv\lib\site-packages\rest_framework\views.py", line 506, in dispatch
    response = handler(request, *args, **kwargs)
  File "C:\Users\takud\OneDrive\Documents\Development\Intelli-Pos\intelliPos\api\views.py", line 49, in post
    pos_id = data['posID']
  File "C:\Users\takud\OneDrive\Documents\Development\Intelli-Pos\intelliPos\venv\lib\site-packages\django\utils\datastructures.py", line 78, in __getitem__
    raise MultiValueDictKeyError(key)
django.utils.datastructures.MultiValueDictKeyError: 'posID'
"POST /api/login/ HTTP/1.1" 500 106579
Internal Server Error: /api/login/
Traceback (most recent call last):
  File "C:\Users\takud\OneDrive\Documents\Development\Intelli-Pos\intelliPos\venv\lib\site-packages\django\utils\datastructures.py", line 76, in __getitem__
    list_ = super().__getitem__(key)
KeyError: 'device'

During handling of the above exception, another exception occurred:

Traceback (most recent call last):
  File "C:\Users\takud\OneDrive\Documents\Development\Intelli-Pos\intelliPos\venv\lib\site-packages\django\core\handlers\exception.py", line 47, in inner
    response = get_response(request)
  File "C:\Users\takud\OneDrive\Documents\Development\Intelli-Pos\intelliPos\venv\lib\site-packages\django\core\handlers\base.py", line 181, in _get_response
    response = wrapped_callback(request, *callback_args, **callback_kwargs)
  File "C:\Users\takud\OneDrive\Documents\Development\Intelli-Pos\intelliPos\venv\lib\site-packages\django\views\decorators\csrf.py", line 54, in wrapped_view
    return view_func(*args, **kwargs)
  File "C:\Users\takud\OneDrive\Documents\Development\Intelli-Pos\intelliPos\venv\lib\site-packages\django\views\generic\base.py", line 70, in view
    return self.dispatch(request, *args, **kwargs)
  File "C:\Users\takud\OneDrive\Documents\Development\Intelli-Pos\intelliPos\venv\lib\site-packages\rest_framework\views.py", line 509, in dispatch
    response = self.handle_exception(exc)
  File "C:\Users\takud\OneDrive\Documents\Development\Intelli-Pos\intelliPos\venv\lib\site-packages\rest_framework\views.py", line 469, in handle_exception
    self.raise_uncaught_exception(exc)
  File "C:\Users\takud\OneDrive\Documents\Development\Intelli-Pos\intelliPos\venv\lib\site-packages\rest_framework\views.py", line 480, in raise_uncaught_exception
    raise exc
  File "C:\Users\takud\OneDrive\Documents\Development\Intelli-Pos\intelliPos\venv\lib\site-packages\rest_framework\views.py", line 506, in dispatch
    response = handler(request, *args, **kwargs)
  File "C:\Users\takud\OneDrive\Documents\Development\Intelli-Pos\intelliPos\api\views.py", line 50, in post
    device = data['device']
  File "C:\Users\takud\OneDrive\Documents\Development\Intelli-Pos\intelliPos\venv\lib\site-packages\django\utils\datastructures.py", line 78, in __getitem__
    raise MultiValueDictKeyError(key)
django.utils.datastructures.MultiValueDictKeyError: 'device'
"POST /api/login/ HTTP/1.1" 500 106846
Not Found: /api/get_dek
"POST /api/get_dek?key_name=token_key HTTP/1.1" 404 4508
Not Found: /api/get_dek/
"GET /api/get_dek/ HTTP/1.1" 404 4491
Internal Server Error: /api/get_dek/token_key
Traceback (most recent call last):
  File "C:\Users\takud\OneDrive\Documents\Development\Intelli-Pos\intelliPos\venv\lib\site-packages\django\core\handlers\exception.py", line 47, in inner
    response = get_response(request)
  File "C:\Users\takud\OneDrive\Documents\Development\Intelli-Pos\intelliPos\venv\lib\site-packages\django\core\handlers\base.py", line 181, in _get_response
    response = wrapped_callback(request, *callback_args, **callback_kwargs)
  File "C:\Users\takud\OneDrive\Documents\Development\Intelli-Pos\intelliPos\venv\lib\site-packages\django\views\decorators\csrf.py", line 54, in wrapped_view
    return view_func(*args, **kwargs)
  File "C:\Users\takud\OneDrive\Documents\Development\Intelli-Pos\intelliPos\venv\lib\site-packages\django\views\generic\base.py", line 70, in view
    return self.dispatch(request, *args, **kwargs)
  File "C:\Users\takud\OneDrive\Documents\Development\Intelli-Pos\intelliPos\venv\lib\site-packages\rest_framework\views.py", line 509, in dispatch
    response = self.handle_exception(exc)
  File "C:\Users\takud\OneDrive\Documents\Development\Intelli-Pos\intelliPos\venv\lib\site-packages\rest_framework\views.py", line 469, in handle_exception
    self.raise_uncaught_exception(exc)
  File "C:\Users\takud\OneDrive\Documents\Development\Intelli-Pos\intelliPos\venv\lib\site-packages\rest_framework\views.py", line 480, in raise_uncaught_exception
    raise exc
  File "C:\Users\takud\OneDrive\Documents\Development\Intelli-Pos\intelliPos\venv\lib\site-packages\rest_framework\views.py", line 506, in dispatch
    response = handler(request, *args, **kwargs)
TypeError: get() got multiple values for argument 'key_name'
"GET /api/get_dek/token_key HTTP/1.1" 500 93402
Not Found: /api/get_dek/token_key
"GET /api/get_dek/token_key HTTP/1.1" 404 4502
Internal Server Error: /api/get_dek/
Traceback (most recent call last):
  File "C:\Users\takud\OneDrive\Documents\Development\Intelli-Pos\intelliPos\venv\lib\site-packages\django\core\handlers\exception.py", line 47, in inner
    response = get_response(request)
  File "C:\Users\takud\OneDrive\Documents\Development\Intelli-Pos\intelliPos\venv\lib\site-packages\django\core\handlers\base.py", line 181, in _get_response
    response = wrapped_callback(request, *callback_args, **callback_kwargs)
  File "C:\Users\takud\OneDrive\Documents\Development\Intelli-Pos\intelliPos\venv\lib\site-packages\django\views\decorators\csrf.py", line 54, in wrapped_view
    return view_func(*args, **kwargs)
  File "C:\Users\takud\OneDrive\Documents\Development\Intelli-Pos\intelliPos\venv\lib\site-packages\django\views\generic\base.py", line 70, in view
    return self.dispatch(request, *args, **kwargs)
  File "C:\Users\takud\OneDrive\Documents\Development\Intelli-Pos\intelliPos\venv\lib\site-packages\rest_framework\views.py", line 509, in dispatch
    response = self.handle_exception(exc)
  File "C:\Users\takud\OneDrive\Documents\Development\Intelli-Pos\intelliPos\venv\lib\site-packages\rest_framework\views.py", line 469, in handle_exception
    self.raise_uncaught_exception(exc)
  File "C:\Users\takud\OneDrive\Documents\Development\Intelli-Pos\intelliPos\venv\lib\site-packages\rest_framework\views.py", line 480, in raise_uncaught_exception
    raise exc
  File "C:\Users\takud\OneDrive\Documents\Development\Intelli-Pos\intelliPos\venv\lib\site-packages\rest_framework\views.py", line 506, in dispatch
    response = handler(request, *args, **kwargs)
TypeError: get() takes 1 positional argument but 2 were given
"GET /api/get_dek/ HTTP/1.1" 500 93110
Internal Server Error: /api/get_dek/
Traceback (most recent call last):
  File "C:\Users\takud\OneDrive\Documents\Development\Intelli-Pos\intelliPos\venv\lib\site-packages\urllib3\connection.py", line 170, in _new_conn
    (self._dns_host, self.port), self.timeout, **extra_kw
  File "C:\Users\takud\OneDrive\Documents\Development\Intelli-Pos\intelliPos\venv\lib\site-packages\urllib3\util\connection.py", line 96, in create_connection
    raise err
  File "C:\Users\takud\OneDrive\Documents\Development\Intelli-Pos\intelliPos\venv\lib\site-packages\urllib3\util\connection.py", line 86, in create_connection
    sock.connect(sa)
TimeoutError: [WinError 10060] A connection attempt failed because the connected party did not properly respond after a period of time, or established connection failed because connected host has failed to respond

During handling of the above exception, another exception occurred:

Traceback (most recent call last):
  File "C:\Users\takud\OneDrive\Documents\Development\Intelli-Pos\intelliPos\venv\lib\site-packages\urllib3\connectionpool.py", line 706, in urlopen
    chunked=chunked,
  File "C:\Users\takud\OneDrive\Documents\Development\Intelli-Pos\intelliPos\venv\lib\site-packages\urllib3\connectionpool.py", line 394, in _make_request
    conn.request(method, url, **httplib_request_kw)
  File "C:\Users\takud\OneDrive\Documents\Development\Intelli-Pos\intelliPos\venv\lib\site-packages\urllib3\connection.py", line 234, in request
    super(HTTPConnection, self).request(method, url, body=body, headers=headers)
  File "c:\users\takud\appdata\local\programs\python\python37\lib\http\client.py", line 1244, in request
    self._send_request(method, url, body, headers, encode_chunked)
  File "c:\users\takud\appdata\local\programs\python\python37\lib\http\client.py", line 1290, in _send_request
    self.endheaders(body, encode_chunked=encode_chunked)
  File "c:\users\takud\appdata\local\programs\python\python37\lib\http\client.py", line 1239, in endheaders
    self._send_output(message_body, encode_chunked=encode_chunked)
  File "c:\users\takud\appdata\local\programs\python\python37\lib\http\client.py", line 1026, in _send_output
    self.send(msg)
  File "c:\users\takud\appdata\local\programs\python\python37\lib\http\client.py", line 966, in send
    self.connect()
  File "C:\Users\takud\OneDrive\Documents\Development\Intelli-Pos\intelliPos\venv\lib\site-packages\urllib3\connection.py", line 200, in connect
    conn = self._new_conn()
  File "C:\Users\takud\OneDrive\Documents\Development\Intelli-Pos\intelliPos\venv\lib\site-packages\urllib3\connection.py", line 182, in _new_conn
    self, "Failed to establish a new connection: %s" % e
urllib3.exceptions.NewConnectionError: <urllib3.connection.HTTPConnection object at 0x0000011CD063F348>: Failed to establish a new connection: [WinError 10060] A connection attempt failed because the connected party did not properly respond after a period of time, or established connection failed because connected host has failed to respond

During handling of the above exception, another exception occurred:

Traceback (most recent call last):
  File "C:\Users\takud\OneDrive\Documents\Development\Intelli-Pos\intelliPos\venv\lib\site-packages\requests\adapters.py", line 449, in send
    timeout=timeout
  File "C:\Users\takud\OneDrive\Documents\Development\Intelli-Pos\intelliPos\venv\lib\site-packages\urllib3\connectionpool.py", line 756, in urlopen
    method, url, error=e, _pool=self, _stacktrace=sys.exc_info()[2]
  File "C:\Users\takud\OneDrive\Documents\Development\Intelli-Pos\intelliPos\venv\lib\site-packages\urllib3\util\retry.py", line 573, in increment
    raise MaxRetryError(_pool, url, error or ResponseError(cause))
urllib3.exceptions.MaxRetryError: HTTPConnectionPool(host='45.55.44.41', port=8003): Max retries exceeded with url: /api/v1/keys?key_nametoken_key (Caused by NewConnectionError('<urllib3.connection.HTTPConnection object at 0x0000011CD063F348>: Failed to establish a new connection: [WinError 10060] A connection attempt failed because the connected party did not properly respond after a period of time, or established connection failed because connected host has failed to respond'))

During handling of the above exception, another exception occurred:

Traceback (most recent call last):
  File "C:\Users\takud\OneDrive\Documents\Development\Intelli-Pos\intelliPos\venv\lib\site-packages\django\core\handlers\exception.py", line 47, in inner
    response = get_response(request)
  File "C:\Users\takud\OneDrive\Documents\Development\Intelli-Pos\intelliPos\venv\lib\site-packages\django\core\handlers\base.py", line 181, in _get_response
    response = wrapped_callback(request, *callback_args, **callback_kwargs)
  File "C:\Users\takud\OneDrive\Documents\Development\Intelli-Pos\intelliPos\venv\lib\site-packages\django\views\decorators\csrf.py", line 54, in wrapped_view
    return view_func(*args, **kwargs)
  File "C:\Users\takud\OneDrive\Documents\Development\Intelli-Pos\intelliPos\venv\lib\site-packages\django\views\generic\base.py", line 70, in view
    return self.dispatch(request, *args, **kwargs)
  File "C:\Users\takud\OneDrive\Documents\Development\Intelli-Pos\intelliPos\venv\lib\site-packages\rest_framework\views.py", line 509, in dispatch
    response = self.handle_exception(exc)
  File "C:\Users\takud\OneDrive\Documents\Development\Intelli-Pos\intelliPos\venv\lib\site-packages\rest_framework\views.py", line 469, in handle_exception
    self.raise_uncaught_exception(exc)
  File "C:\Users\takud\OneDrive\Documents\Development\Intelli-Pos\intelliPos\venv\lib\site-packages\rest_framework\views.py", line 480, in raise_uncaught_exception
    raise exc
  File "C:\Users\takud\OneDrive\Documents\Development\Intelli-Pos\intelliPos\venv\lib\site-packages\rest_framework\views.py", line 506, in dispatch
    response = handler(request, *args, **kwargs)
  File "C:\Users\takud\OneDrive\Documents\Development\Intelli-Pos\intelliPos\api\views.py", line 49, in get
    r = requests.get(url, headers=headers)
  File "C:\Users\takud\OneDrive\Documents\Development\Intelli-Pos\intelliPos\venv\lib\site-packages\requests\api.py", line 76, in get
    return request('get', url, params=params, **kwargs)
  File "C:\Users\takud\OneDrive\Documents\Development\Intelli-Pos\intelliPos\venv\lib\site-packages\requests\api.py", line 61, in request
    return session.request(method=method, url=url, **kwargs)
  File "C:\Users\takud\OneDrive\Documents\Development\Intelli-Pos\intelliPos\venv\lib\site-packages\requests\sessions.py", line 542, in request
    resp = self.send(prep, **send_kwargs)
  File "C:\Users\takud\OneDrive\Documents\Development\Intelli-Pos\intelliPos\venv\lib\site-packages\requests\sessions.py", line 655, in send
    r = adapter.send(request, **kwargs)
  File "C:\Users\takud\OneDrive\Documents\Development\Intelli-Pos\intelliPos\venv\lib\site-packages\requests\adapters.py", line 516, in send
    raise ConnectionError(e, request=request)
requests.exceptions.ConnectionError: HTTPConnectionPool(host='45.55.44.41', port=8003): Max retries exceeded with url: /api/v1/keys?key_nametoken_key (Caused by NewConnectionError('<urllib3.connection.HTTPConnection object at 0x0000011CD063F348>: Failed to establish a new connection: [WinError 10060] A connection attempt failed because the connected party did not properly respond after a period of time, or established connection failed because connected host has failed to respond'))
"GET /api/get_dek/ HTTP/1.1" 500 220706
Internal Server Error: /api/get_dek/
Traceback (most recent call last):
  File "C:\Users\takud\OneDrive\Documents\Development\Intelli-Pos\intelliPos\venv\lib\site-packages\django\core\handlers\exception.py", line 47, in inner
    response = get_response(request)
  File "C:\Users\takud\OneDrive\Documents\Development\Intelli-Pos\intelliPos\venv\lib\site-packages\django\core\handlers\base.py", line 181, in _get_response
    response = wrapped_callback(request, *callback_args, **callback_kwargs)
  File "C:\Users\takud\OneDrive\Documents\Development\Intelli-Pos\intelliPos\venv\lib\site-packages\django\views\decorators\csrf.py", line 54, in wrapped_view
    return view_func(*args, **kwargs)
  File "C:\Users\takud\OneDrive\Documents\Development\Intelli-Pos\intelliPos\venv\lib\site-packages\django\views\generic\base.py", line 70, in view
    return self.dispatch(request, *args, **kwargs)
  File "C:\Users\takud\OneDrive\Documents\Development\Intelli-Pos\intelliPos\venv\lib\site-packages\rest_framework\views.py", line 509, in dispatch
    response = self.handle_exception(exc)
  File "C:\Users\takud\OneDrive\Documents\Development\Intelli-Pos\intelliPos\venv\lib\site-packages\rest_framework\views.py", line 469, in handle_exception
    self.raise_uncaught_exception(exc)
  File "C:\Users\takud\OneDrive\Documents\Development\Intelli-Pos\intelliPos\venv\lib\site-packages\rest_framework\views.py", line 480, in raise_uncaught_exception
    raise exc
  File "C:\Users\takud\OneDrive\Documents\Development\Intelli-Pos\intelliPos\venv\lib\site-packages\rest_framework\views.py", line 506, in dispatch
    response = handler(request, *args, **kwargs)
  File "C:\Users\takud\OneDrive\Documents\Development\Intelli-Pos\intelliPos\api\views.py", line 45, in get
    key_name = request.data['key_name']
KeyError: 'key_name'
"GET /api/get_dek/ HTTP/1.1" 500 96837
Internal Server Error: /api/get_dek/
Traceback (most recent call last):
  File "C:\Users\takud\OneDrive\Documents\Development\Intelli-Pos\intelliPos\venv\lib\site-packages\django\core\handlers\exception.py", line 47, in inner
    response = get_response(request)
  File "C:\Users\takud\OneDrive\Documents\Development\Intelli-Pos\intelliPos\venv\lib\site-packages\django\core\handlers\base.py", line 181, in _get_response
    response = wrapped_callback(request, *callback_args, **callback_kwargs)
  File "C:\Users\takud\OneDrive\Documents\Development\Intelli-Pos\intelliPos\venv\lib\site-packages\django\views\decorators\csrf.py", line 54, in wrapped_view
    return view_func(*args, **kwargs)
  File "C:\Users\takud\OneDrive\Documents\Development\Intelli-Pos\intelliPos\venv\lib\site-packages\django\views\generic\base.py", line 70, in view
    return self.dispatch(request, *args, **kwargs)
  File "C:\Users\takud\OneDrive\Documents\Development\Intelli-Pos\intelliPos\venv\lib\site-packages\rest_framework\views.py", line 509, in dispatch
    response = self.handle_exception(exc)
  File "C:\Users\takud\OneDrive\Documents\Development\Intelli-Pos\intelliPos\venv\lib\site-packages\rest_framework\views.py", line 469, in handle_exception
    self.raise_uncaught_exception(exc)
  File "C:\Users\takud\OneDrive\Documents\Development\Intelli-Pos\intelliPos\venv\lib\site-packages\rest_framework\views.py", line 480, in raise_uncaught_exception
    raise exc
  File "C:\Users\takud\OneDrive\Documents\Development\Intelli-Pos\intelliPos\venv\lib\site-packages\rest_framework\views.py", line 506, in dispatch
    response = handler(request, *args, **kwargs)
  File "C:\Users\takud\OneDrive\Documents\Development\Intelli-Pos\intelliPos\api\views.py", line 46, in get
    url = 'http://45.55.44.41:8003/api/v1/keys?key_name' + key_name
TypeError: can only concatenate str (not "NoneType") to str
"GET /api/get_dek/ HTTP/1.1" 500 97256
Internal Server Error: /api/get_dek/
Traceback (most recent call last):
  File "C:\Users\takud\OneDrive\Documents\Development\Intelli-Pos\intelliPos\venv\lib\site-packages\rest_framework\request.py", line 416, in __getattr__
    return getattr(self._request, attr)
AttributeError: 'WSGIRequest' object has no attribute 'args'

During handling of the above exception, another exception occurred:

Traceback (most recent call last):
  File "C:\Users\takud\OneDrive\Documents\Development\Intelli-Pos\intelliPos\venv\lib\site-packages\django\core\handlers\exception.py", line 47, in inner
    response = get_response(request)
  File "C:\Users\takud\OneDrive\Documents\Development\Intelli-Pos\intelliPos\venv\lib\site-packages\django\core\handlers\base.py", line 181, in _get_response
    response = wrapped_callback(request, *callback_args, **callback_kwargs)
  File "C:\Users\takud\OneDrive\Documents\Development\Intelli-Pos\intelliPos\venv\lib\site-packages\django\views\decorators\csrf.py", line 54, in wrapped_view
    return view_func(*args, **kwargs)
  File "C:\Users\takud\OneDrive\Documents\Development\Intelli-Pos\intelliPos\venv\lib\site-packages\django\views\generic\base.py", line 70, in view
    return self.dispatch(request, *args, **kwargs)
  File "C:\Users\takud\OneDrive\Documents\Development\Intelli-Pos\intelliPos\venv\lib\site-packages\rest_framework\views.py", line 509, in dispatch
    response = self.handle_exception(exc)
  File "C:\Users\takud\OneDrive\Documents\Development\Intelli-Pos\intelliPos\venv\lib\site-packages\rest_framework\views.py", line 469, in handle_exception
    self.raise_uncaught_exception(exc)
  File "C:\Users\takud\OneDrive\Documents\Development\Intelli-Pos\intelliPos\venv\lib\site-packages\rest_framework\views.py", line 480, in raise_uncaught_exception
    raise exc
  File "C:\Users\takud\OneDrive\Documents\Development\Intelli-Pos\intelliPos\venv\lib\site-packages\rest_framework\views.py", line 506, in dispatch
    response = handler(request, *args, **kwargs)
  File "C:\Users\takud\OneDrive\Documents\Development\Intelli-Pos\intelliPos\api\views.py", line 45, in get
    key_name = request.args['key_name']
  File "C:\Users\takud\OneDrive\Documents\Development\Intelli-Pos\intelliPos\venv\lib\site-packages\rest_framework\request.py", line 418, in __getattr__
    return self.__getattribute__(attr)
AttributeError: 'Request' object has no attribute 'args'
"GET /api/get_dek/ HTTP/1.1" 500 105361
Internal Server Error: /api/get_dek/
Traceback (most recent call last):
  File "C:\Users\takud\OneDrive\Documents\Development\Intelli-Pos\intelliPos\venv\lib\site-packages\rest_framework\request.py", line 416, in __getattr__
    return getattr(self._request, attr)
AttributeError: 'WSGIRequest' object has no attribute 'args'

During handling of the above exception, another exception occurred:

Traceback (most recent call last):
  File "C:\Users\takud\OneDrive\Documents\Development\Intelli-Pos\intelliPos\venv\lib\site-packages\django\core\handlers\exception.py", line 47, in inner
    response = get_response(request)
  File "C:\Users\takud\OneDrive\Documents\Development\Intelli-Pos\intelliPos\venv\lib\site-packages\django\core\handlers\base.py", line 181, in _get_response
    response = wrapped_callback(request, *callback_args, **callback_kwargs)
  File "C:\Users\takud\OneDrive\Documents\Development\Intelli-Pos\intelliPos\venv\lib\site-packages\django\views\decorators\csrf.py", line 54, in wrapped_view
    return view_func(*args, **kwargs)
  File "C:\Users\takud\OneDrive\Documents\Development\Intelli-Pos\intelliPos\venv\lib\site-packages\django\views\generic\base.py", line 70, in view
    return self.dispatch(request, *args, **kwargs)
  File "C:\Users\takud\OneDrive\Documents\Development\Intelli-Pos\intelliPos\venv\lib\site-packages\rest_framework\views.py", line 509, in dispatch
    response = self.handle_exception(exc)
  File "C:\Users\takud\OneDrive\Documents\Development\Intelli-Pos\intelliPos\venv\lib\site-packages\rest_framework\views.py", line 469, in handle_exception
    self.raise_uncaught_exception(exc)
  File "C:\Users\takud\OneDrive\Documents\Development\Intelli-Pos\intelliPos\venv\lib\site-packages\rest_framework\views.py", line 480, in raise_uncaught_exception
    raise exc
  File "C:\Users\takud\OneDrive\Documents\Development\Intelli-Pos\intelliPos\venv\lib\site-packages\rest_framework\views.py", line 506, in dispatch
    response = handler(request, *args, **kwargs)
  File "C:\Users\takud\OneDrive\Documents\Development\Intelli-Pos\intelliPos\api\views.py", line 45, in get
    args = request.args
  File "C:\Users\takud\OneDrive\Documents\Development\Intelli-Pos\intelliPos\venv\lib\site-packages\rest_framework\request.py", line 418, in __getattr__
    return self.__getattribute__(attr)
AttributeError: 'Request' object has no attribute 'args'
"GET /api/get_dek/ HTTP/1.1" 500 105323
Internal Server Error: /api/get_dek/
Traceback (most recent call last):
  File "C:\Users\takud\OneDrive\Documents\Development\Intelli-Pos\intelliPos\venv\lib\site-packages\django\core\handlers\exception.py", line 47, in inner
    response = get_response(request)
  File "C:\Users\takud\OneDrive\Documents\Development\Intelli-Pos\intelliPos\venv\lib\site-packages\django\core\handlers\base.py", line 181, in _get_response
    response = wrapped_callback(request, *callback_args, **callback_kwargs)
  File "C:\Users\takud\OneDrive\Documents\Development\Intelli-Pos\intelliPos\venv\lib\site-packages\django\views\decorators\csrf.py", line 54, in wrapped_view
    return view_func(*args, **kwargs)
  File "C:\Users\takud\OneDrive\Documents\Development\Intelli-Pos\intelliPos\venv\lib\site-packages\django\views\generic\base.py", line 70, in view
    return self.dispatch(request, *args, **kwargs)
  File "C:\Users\takud\OneDrive\Documents\Development\Intelli-Pos\intelliPos\venv\lib\site-packages\rest_framework\views.py", line 509, in dispatch
    response = self.handle_exception(exc)
  File "C:\Users\takud\OneDrive\Documents\Development\Intelli-Pos\intelliPos\venv\lib\site-packages\rest_framework\views.py", line 469, in handle_exception
    self.raise_uncaught_exception(exc)
  File "C:\Users\takud\OneDrive\Documents\Development\Intelli-Pos\intelliPos\venv\lib\site-packages\rest_framework\views.py", line 480, in raise_uncaught_exception
    raise exc
  File "C:\Users\takud\OneDrive\Documents\Development\Intelli-Pos\intelliPos\venv\lib\site-packages\rest_framework\views.py", line 506, in dispatch
    response = handler(request, *args, **kwargs)
  File "C:\Users\takud\OneDrive\Documents\Development\Intelli-Pos\intelliPos\api\views.py", line 46, in get
    url = 'http://45.55.44.41:8003/api/v1/keys?key_name' + key_name
TypeError: can only concatenate str (not "NoneType") to str
"GET /api/get_dek/ HTTP/1.1" 500 97256
Internal Server Error: /api/get_dek/
Traceback (most recent call last):
  File "C:\Users\takud\OneDrive\Documents\Development\Intelli-Pos\intelliPos\venv\lib\site-packages\django\utils\datastructures.py", line 76, in __getitem__
    list_ = super().__getitem__(key)
KeyError: 'key_name'

During handling of the above exception, another exception occurred:

Traceback (most recent call last):
  File "C:\Users\takud\OneDrive\Documents\Development\Intelli-Pos\intelliPos\venv\lib\site-packages\django\core\handlers\exception.py", line 47, in inner
    response = get_response(request)
  File "C:\Users\takud\OneDrive\Documents\Development\Intelli-Pos\intelliPos\venv\lib\site-packages\django\core\handlers\base.py", line 181, in _get_response
    response = wrapped_callback(request, *callback_args, **callback_kwargs)
  File "C:\Users\takud\OneDrive\Documents\Development\Intelli-Pos\intelliPos\venv\lib\site-packages\django\views\decorators\csrf.py", line 54, in wrapped_view
    return view_func(*args, **kwargs)
  File "C:\Users\takud\OneDrive\Documents\Development\Intelli-Pos\intelliPos\venv\lib\site-packages\django\views\generic\base.py", line 70, in view
    return self.dispatch(request, *args, **kwargs)
  File "C:\Users\takud\OneDrive\Documents\Development\Intelli-Pos\intelliPos\venv\lib\site-packages\rest_framework\views.py", line 509, in dispatch
    response = self.handle_exception(exc)
  File "C:\Users\takud\OneDrive\Documents\Development\Intelli-Pos\intelliPos\venv\lib\site-packages\rest_framework\views.py", line 469, in handle_exception
    self.raise_uncaught_exception(exc)
  File "C:\Users\takud\OneDrive\Documents\Development\Intelli-Pos\intelliPos\venv\lib\site-packages\rest_framework\views.py", line 480, in raise_uncaught_exception
    raise exc
  File "C:\Users\takud\OneDrive\Documents\Development\Intelli-Pos\intelliPos\venv\lib\site-packages\rest_framework\views.py", line 506, in dispatch
    response = handler(request, *args, **kwargs)
  File "C:\Users\takud\OneDrive\Documents\Development\Intelli-Pos\intelliPos\api\views.py", line 45, in get
    key_name = request.GET['key_name']
  File "C:\Users\takud\OneDrive\Documents\Development\Intelli-Pos\intelliPos\venv\lib\site-packages\django\utils\datastructures.py", line 78, in __getitem__
    raise MultiValueDictKeyError(key)
django.utils.datastructures.MultiValueDictKeyError: 'key_name'
"GET /api/get_dek/ HTTP/1.1" 500 105286
Internal Server Error: /api/get_dek/
Traceback (most recent call last):
  File "C:\Users\takud\OneDrive\Documents\Development\Intelli-Pos\intelliPos\venv\lib\site-packages\django\core\handlers\exception.py", line 47, in inner
    response = get_response(request)
  File "C:\Users\takud\OneDrive\Documents\Development\Intelli-Pos\intelliPos\venv\lib\site-packages\django\core\handlers\base.py", line 181, in _get_response
    response = wrapped_callback(request, *callback_args, **callback_kwargs)
  File "C:\Users\takud\OneDrive\Documents\Development\Intelli-Pos\intelliPos\venv\lib\site-packages\django\views\decorators\csrf.py", line 54, in wrapped_view
    return view_func(*args, **kwargs)
  File "C:\Users\takud\OneDrive\Documents\Development\Intelli-Pos\intelliPos\venv\lib\site-packages\django\views\generic\base.py", line 70, in view
    return self.dispatch(request, *args, **kwargs)
  File "C:\Users\takud\OneDrive\Documents\Development\Intelli-Pos\intelliPos\venv\lib\site-packages\rest_framework\views.py", line 509, in dispatch
    response = self.handle_exception(exc)
  File "C:\Users\takud\OneDrive\Documents\Development\Intelli-Pos\intelliPos\venv\lib\site-packages\rest_framework\views.py", line 469, in handle_exception
    self.raise_uncaught_exception(exc)
  File "C:\Users\takud\OneDrive\Documents\Development\Intelli-Pos\intelliPos\venv\lib\site-packages\rest_framework\views.py", line 480, in raise_uncaught_exception
    raise exc
  File "C:\Users\takud\OneDrive\Documents\Development\Intelli-Pos\intelliPos\venv\lib\site-packages\rest_framework\views.py", line 506, in dispatch
    response = handler(request, *args, **kwargs)
  File "C:\Users\takud\OneDrive\Documents\Development\Intelli-Pos\intelliPos\api\views.py", line 46, in get
    url = 'http://45.55.44.41:8003/api/v1/keys?key_name' + key_name
TypeError: can only concatenate str (not "NoneType") to str
"GET /api/get_dek/ HTTP/1.1" 500 97261
Internal Server Error: /api/get_dek/
Traceback (most recent call last):
  File "C:\Users\takud\OneDrive\Documents\Development\Intelli-Pos\intelliPos\venv\lib\site-packages\urllib3\connection.py", line 170, in _new_conn
    (self._dns_host, self.port), self.timeout, **extra_kw
  File "C:\Users\takud\OneDrive\Documents\Development\Intelli-Pos\intelliPos\venv\lib\site-packages\urllib3\util\connection.py", line 96, in create_connection
    raise err
  File "C:\Users\takud\OneDrive\Documents\Development\Intelli-Pos\intelliPos\venv\lib\site-packages\urllib3\util\connection.py", line 86, in create_connection
    sock.connect(sa)
ConnectionRefusedError: [WinError 10061] No connection could be made because the target machine actively refused it

During handling of the above exception, another exception occurred:

Traceback (most recent call last):
  File "C:\Users\takud\OneDrive\Documents\Development\Intelli-Pos\intelliPos\venv\lib\site-packages\urllib3\connectionpool.py", line 706, in urlopen
    chunked=chunked,
  File "C:\Users\takud\OneDrive\Documents\Development\Intelli-Pos\intelliPos\venv\lib\site-packages\urllib3\connectionpool.py", line 394, in _make_request
    conn.request(method, url, **httplib_request_kw)
  File "C:\Users\takud\OneDrive\Documents\Development\Intelli-Pos\intelliPos\venv\lib\site-packages\urllib3\connection.py", line 234, in request
    super(HTTPConnection, self).request(method, url, body=body, headers=headers)
  File "c:\users\takud\appdata\local\programs\python\python37\lib\http\client.py", line 1244, in request
    self._send_request(method, url, body, headers, encode_chunked)
  File "c:\users\takud\appdata\local\programs\python\python37\lib\http\client.py", line 1290, in _send_request
    self.endheaders(body, encode_chunked=encode_chunked)
  File "c:\users\takud\appdata\local\programs\python\python37\lib\http\client.py", line 1239, in endheaders
    self._send_output(message_body, encode_chunked=encode_chunked)
  File "c:\users\takud\appdata\local\programs\python\python37\lib\http\client.py", line 1026, in _send_output
    self.send(msg)
  File "c:\users\takud\appdata\local\programs\python\python37\lib\http\client.py", line 966, in send
    self.connect()
  File "C:\Users\takud\OneDrive\Documents\Development\Intelli-Pos\intelliPos\venv\lib\site-packages\urllib3\connection.py", line 200, in connect
    conn = self._new_conn()
  File "C:\Users\takud\OneDrive\Documents\Development\Intelli-Pos\intelliPos\venv\lib\site-packages\urllib3\connection.py", line 182, in _new_conn
    self, "Failed to establish a new connection: %s" % e
urllib3.exceptions.NewConnectionError: <urllib3.connection.HTTPConnection object at 0x000002DC3604C748>: Failed to establish a new connection: [WinError 10061] No connection could be made because the target machine actively refused it

During handling of the above exception, another exception occurred:

Traceback (most recent call last):
  File "C:\Users\takud\OneDrive\Documents\Development\Intelli-Pos\intelliPos\venv\lib\site-packages\requests\adapters.py", line 449, in send
    timeout=timeout
  File "C:\Users\takud\OneDrive\Documents\Development\Intelli-Pos\intelliPos\venv\lib\site-packages\urllib3\connectionpool.py", line 756, in urlopen
    method, url, error=e, _pool=self, _stacktrace=sys.exc_info()[2]
  File "C:\Users\takud\OneDrive\Documents\Development\Intelli-Pos\intelliPos\venv\lib\site-packages\urllib3\util\retry.py", line 573, in increment
    raise MaxRetryError(_pool, url, error or ResponseError(cause))
urllib3.exceptions.MaxRetryError: HTTPConnectionPool(host='45.55.44.41', port=8003): Max retries exceeded with url: /api/v1/keys?key_nametoken_key (Caused by NewConnectionError('<urllib3.connection.HTTPConnection object at 0x000002DC3604C748>: Failed to establish a new connection: [WinError 10061] No connection could be made because the target machine actively refused it'))

During handling of the above exception, another exception occurred:

Traceback (most recent call last):
  File "C:\Users\takud\OneDrive\Documents\Development\Intelli-Pos\intelliPos\venv\lib\site-packages\django\core\handlers\exception.py", line 47, in inner
    response = get_response(request)
  File "C:\Users\takud\OneDrive\Documents\Development\Intelli-Pos\intelliPos\venv\lib\site-packages\django\core\handlers\base.py", line 181, in _get_response
    response = wrapped_callback(request, *callback_args, **callback_kwargs)
  File "C:\Users\takud\OneDrive\Documents\Development\Intelli-Pos\intelliPos\venv\lib\site-packages\django\views\decorators\csrf.py", line 54, in wrapped_view
    return view_func(*args, **kwargs)
  File "C:\Users\takud\OneDrive\Documents\Development\Intelli-Pos\intelliPos\venv\lib\site-packages\django\views\generic\base.py", line 70, in view
    return self.dispatch(request, *args, **kwargs)
  File "C:\Users\takud\OneDrive\Documents\Development\Intelli-Pos\intelliPos\venv\lib\site-packages\rest_framework\views.py", line 509, in dispatch
    response = self.handle_exception(exc)
  File "C:\Users\takud\OneDrive\Documents\Development\Intelli-Pos\intelliPos\venv\lib\site-packages\rest_framework\views.py", line 469, in handle_exception
    self.raise_uncaught_exception(exc)
  File "C:\Users\takud\OneDrive\Documents\Development\Intelli-Pos\intelliPos\venv\lib\site-packages\rest_framework\views.py", line 480, in raise_uncaught_exception
    raise exc
  File "C:\Users\takud\OneDrive\Documents\Development\Intelli-Pos\intelliPos\venv\lib\site-packages\rest_framework\views.py", line 506, in dispatch
    response = handler(request, *args, **kwargs)
  File "C:\Users\takud\OneDrive\Documents\Development\Intelli-Pos\intelliPos\api\views.py", line 49, in get
    r = requests.get(url, headers=headers)
  File "C:\Users\takud\OneDrive\Documents\Development\Intelli-Pos\intelliPos\venv\lib\site-packages\requests\api.py", line 76, in get
    return request('get', url, params=params, **kwargs)
  File "C:\Users\takud\OneDrive\Documents\Development\Intelli-Pos\intelliPos\venv\lib\site-packages\requests\api.py", line 61, in request
    return session.request(method=method, url=url, **kwargs)
  File "C:\Users\takud\OneDrive\Documents\Development\Intelli-Pos\intelliPos\venv\lib\site-packages\requests\sessions.py", line 542, in request
    resp = self.send(prep, **send_kwargs)
  File "C:\Users\takud\OneDrive\Documents\Development\Intelli-Pos\intelliPos\venv\lib\site-packages\requests\sessions.py", line 655, in send
    r = adapter.send(request, **kwargs)
  File "C:\Users\takud\OneDrive\Documents\Development\Intelli-Pos\intelliPos\venv\lib\site-packages\requests\adapters.py", line 516, in send
    raise ConnectionError(e, request=request)
requests.exceptions.ConnectionError: HTTPConnectionPool(host='45.55.44.41', port=8003): Max retries exceeded with url: /api/v1/keys?key_nametoken_key (Caused by NewConnectionError('<urllib3.connection.HTTPConnection object at 0x000002DC3604C748>: Failed to establish a new connection: [WinError 10061] No connection could be made because the target machine actively refused it'))
"GET /api/get_dek/?key_name=token_key HTTP/1.1" 500 219564
Internal Server Error: /api/get_dek/
Traceback (most recent call last):
  File "C:\Users\takud\OneDrive\Documents\Development\Intelli-Pos\intelliPos\venv\lib\site-packages\urllib3\connection.py", line 170, in _new_conn
    (self._dns_host, self.port), self.timeout, **extra_kw
  File "C:\Users\takud\OneDrive\Documents\Development\Intelli-Pos\intelliPos\venv\lib\site-packages\urllib3\util\connection.py", line 96, in create_connection
    raise err
  File "C:\Users\takud\OneDrive\Documents\Development\Intelli-Pos\intelliPos\venv\lib\site-packages\urllib3\util\connection.py", line 86, in create_connection
    sock.connect(sa)
ConnectionRefusedError: [WinError 10061] No connection could be made because the target machine actively refused it

During handling of the above exception, another exception occurred:

Traceback (most recent call last):
  File "C:\Users\takud\OneDrive\Documents\Development\Intelli-Pos\intelliPos\venv\lib\site-packages\urllib3\connectionpool.py", line 706, in urlopen
    chunked=chunked,
  File "C:\Users\takud\OneDrive\Documents\Development\Intelli-Pos\intelliPos\venv\lib\site-packages\urllib3\connectionpool.py", line 394, in _make_request
    conn.request(method, url, **httplib_request_kw)
  File "C:\Users\takud\OneDrive\Documents\Development\Intelli-Pos\intelliPos\venv\lib\site-packages\urllib3\connection.py", line 234, in request
    super(HTTPConnection, self).request(method, url, body=body, headers=headers)
  File "c:\users\takud\appdata\local\programs\python\python37\lib\http\client.py", line 1244, in request
    self._send_request(method, url, body, headers, encode_chunked)
  File "c:\users\takud\appdata\local\programs\python\python37\lib\http\client.py", line 1290, in _send_request
    self.endheaders(body, encode_chunked=encode_chunked)
  File "c:\users\takud\appdata\local\programs\python\python37\lib\http\client.py", line 1239, in endheaders
    self._send_output(message_body, encode_chunked=encode_chunked)
  File "c:\users\takud\appdata\local\programs\python\python37\lib\http\client.py", line 1026, in _send_output
    self.send(msg)
  File "c:\users\takud\appdata\local\programs\python\python37\lib\http\client.py", line 966, in send
    self.connect()
  File "C:\Users\takud\OneDrive\Documents\Development\Intelli-Pos\intelliPos\venv\lib\site-packages\urllib3\connection.py", line 200, in connect
    conn = self._new_conn()
  File "C:\Users\takud\OneDrive\Documents\Development\Intelli-Pos\intelliPos\venv\lib\site-packages\urllib3\connection.py", line 182, in _new_conn
    self, "Failed to establish a new connection: %s" % e
urllib3.exceptions.NewConnectionError: <urllib3.connection.HTTPConnection object at 0x000002B87AC34288>: Failed to establish a new connection: [WinError 10061] No connection could be made because the target machine actively refused it

During handling of the above exception, another exception occurred:

Traceback (most recent call last):
  File "C:\Users\takud\OneDrive\Documents\Development\Intelli-Pos\intelliPos\venv\lib\site-packages\requests\adapters.py", line 449, in send
    timeout=timeout
  File "C:\Users\takud\OneDrive\Documents\Development\Intelli-Pos\intelliPos\venv\lib\site-packages\urllib3\connectionpool.py", line 756, in urlopen
    method, url, error=e, _pool=self, _stacktrace=sys.exc_info()[2]
  File "C:\Users\takud\OneDrive\Documents\Development\Intelli-Pos\intelliPos\venv\lib\site-packages\urllib3\util\retry.py", line 573, in increment
    raise MaxRetryError(_pool, url, error or ResponseError(cause))
urllib3.exceptions.MaxRetryError: HTTPConnectionPool(host='45.55.44.41', port=8003): Max retries exceeded with url: /api/v1/keys?key_name=token_key (Caused by NewConnectionError('<urllib3.connection.HTTPConnection object at 0x000002B87AC34288>: Failed to establish a new connection: [WinError 10061] No connection could be made because the target machine actively refused it'))

During handling of the above exception, another exception occurred:

Traceback (most recent call last):
  File "C:\Users\takud\OneDrive\Documents\Development\Intelli-Pos\intelliPos\venv\lib\site-packages\django\core\handlers\exception.py", line 47, in inner
    response = get_response(request)
  File "C:\Users\takud\OneDrive\Documents\Development\Intelli-Pos\intelliPos\venv\lib\site-packages\django\core\handlers\base.py", line 181, in _get_response
    response = wrapped_callback(request, *callback_args, **callback_kwargs)
  File "C:\Users\takud\OneDrive\Documents\Development\Intelli-Pos\intelliPos\venv\lib\site-packages\django\views\decorators\csrf.py", line 54, in wrapped_view
    return view_func(*args, **kwargs)
  File "C:\Users\takud\OneDrive\Documents\Development\Intelli-Pos\intelliPos\venv\lib\site-packages\django\views\generic\base.py", line 70, in view
    return self.dispatch(request, *args, **kwargs)
  File "C:\Users\takud\OneDrive\Documents\Development\Intelli-Pos\intelliPos\venv\lib\site-packages\rest_framework\views.py", line 509, in dispatch
    response = self.handle_exception(exc)
  File "C:\Users\takud\OneDrive\Documents\Development\Intelli-Pos\intelliPos\venv\lib\site-packages\rest_framework\views.py", line 469, in handle_exception
    self.raise_uncaught_exception(exc)
  File "C:\Users\takud\OneDrive\Documents\Development\Intelli-Pos\intelliPos\venv\lib\site-packages\rest_framework\views.py", line 480, in raise_uncaught_exception
    raise exc
  File "C:\Users\takud\OneDrive\Documents\Development\Intelli-Pos\intelliPos\venv\lib\site-packages\rest_framework\views.py", line 506, in dispatch
    response = handler(request, *args, **kwargs)
  File "C:\Users\takud\OneDrive\Documents\Development\Intelli-Pos\intelliPos\api\views.py", line 49, in get
    r = requests.get(url, headers=headers)
  File "C:\Users\takud\OneDrive\Documents\Development\Intelli-Pos\intelliPos\venv\lib\site-packages\requests\api.py", line 76, in get
    return request('get', url, params=params, **kwargs)
  File "C:\Users\takud\OneDrive\Documents\Development\Intelli-Pos\intelliPos\venv\lib\site-packages\requests\api.py", line 61, in request
    return session.request(method=method, url=url, **kwargs)
  File "C:\Users\takud\OneDrive\Documents\Development\Intelli-Pos\intelliPos\venv\lib\site-packages\requests\sessions.py", line 542, in request
    resp = self.send(prep, **send_kwargs)
  File "C:\Users\takud\OneDrive\Documents\Development\Intelli-Pos\intelliPos\venv\lib\site-packages\requests\sessions.py", line 655, in send
    r = adapter.send(request, **kwargs)
  File "C:\Users\takud\OneDrive\Documents\Development\Intelli-Pos\intelliPos\venv\lib\site-packages\requests\adapters.py", line 516, in send
    raise ConnectionError(e, request=request)
requests.exceptions.ConnectionError: HTTPConnectionPool(host='45.55.44.41', port=8003): Max retries exceeded with url: /api/v1/keys?key_name=token_key (Caused by NewConnectionError('<urllib3.connection.HTTPConnection object at 0x000002B87AC34288>: Failed to establish a new connection: [WinError 10061] No connection could be made because the target machine actively refused it'))
"GET /api/get_dek/?key_name=token_key HTTP/1.1" 500 219590
Internal Server Error: /api/get_dek/
Traceback (most recent call last):
  File "C:\Users\takud\OneDrive\Documents\Development\Intelli-Pos\intelliPos\venv\lib\site-packages\django\core\handlers\exception.py", line 47, in inner
    response = get_response(request)
  File "C:\Users\takud\OneDrive\Documents\Development\Intelli-Pos\intelliPos\venv\lib\site-packages\django\core\handlers\base.py", line 181, in _get_response
    response = wrapped_callback(request, *callback_args, **callback_kwargs)
  File "C:\Users\takud\OneDrive\Documents\Development\Intelli-Pos\intelliPos\venv\lib\site-packages\django\views\decorators\csrf.py", line 54, in wrapped_view
    return view_func(*args, **kwargs)
  File "C:\Users\takud\OneDrive\Documents\Development\Intelli-Pos\intelliPos\venv\lib\site-packages\django\views\generic\base.py", line 70, in view
    return self.dispatch(request, *args, **kwargs)
  File "C:\Users\takud\OneDrive\Documents\Development\Intelli-Pos\intelliPos\venv\lib\site-packages\rest_framework\views.py", line 511, in dispatch
    self.response = self.finalize_response(request, response, *args, **kwargs)
  File "C:\Users\takud\OneDrive\Documents\Development\Intelli-Pos\intelliPos\venv\lib\site-packages\rest_framework\views.py", line 426, in finalize_response
    % type(response)
AssertionError: Expected a `Response`, `HttpResponse` or `HttpStreamingResponse` to be returned from the view, but received a `<class 'NoneType'>`
"GET /api/get_dek/?key_name=token_key HTTP/1.1" 500 85012
Internal Server Error: /api/get_dek/
Traceback (most recent call last):
  File "C:\Users\takud\OneDrive\Documents\Development\Intelli-Pos\intelliPos\venv\lib\site-packages\django\core\handlers\exception.py", line 47, in inner
    response = get_response(request)
  File "C:\Users\takud\OneDrive\Documents\Development\Intelli-Pos\intelliPos\venv\lib\site-packages\django\core\handlers\base.py", line 181, in _get_response
    response = wrapped_callback(request, *callback_args, **callback_kwargs)
  File "C:\Users\takud\OneDrive\Documents\Development\Intelli-Pos\intelliPos\venv\lib\site-packages\django\views\decorators\csrf.py", line 54, in wrapped_view
    return view_func(*args, **kwargs)
  File "C:\Users\takud\OneDrive\Documents\Development\Intelli-Pos\intelliPos\venv\lib\site-packages\django\views\generic\base.py", line 70, in view
    return self.dispatch(request, *args, **kwargs)
  File "C:\Users\takud\OneDrive\Documents\Development\Intelli-Pos\intelliPos\venv\lib\site-packages\rest_framework\views.py", line 509, in dispatch
    response = self.handle_exception(exc)
  File "C:\Users\takud\OneDrive\Documents\Development\Intelli-Pos\intelliPos\venv\lib\site-packages\rest_framework\views.py", line 469, in handle_exception
    self.raise_uncaught_exception(exc)
  File "C:\Users\takud\OneDrive\Documents\Development\Intelli-Pos\intelliPos\venv\lib\site-packages\rest_framework\views.py", line 480, in raise_uncaught_exception
    raise exc
  File "C:\Users\takud\OneDrive\Documents\Development\Intelli-Pos\intelliPos\venv\lib\site-packages\rest_framework\views.py", line 506, in dispatch
    response = handler(request, *args, **kwargs)
  File "C:\Users\takud\OneDrive\Documents\Development\Intelli-Pos\intelliPos\api\views.py", line 53, in get
    return JsonResponse(status=200, data=r.jso())
AttributeError: 'Response' object has no attribute 'jso'
"GET /api/get_dek/?key_name=token_key HTTP/1.1" 500 99246
Internal Server Error: /api/get_dek/
Traceback (most recent call last):
  File "C:\Users\takud\OneDrive\Documents\Development\Intelli-Pos\intelliPos\venv\lib\site-packages\django\core\handlers\exception.py", line 47, in inner
    response = get_response(request)
  File "C:\Users\takud\OneDrive\Documents\Development\Intelli-Pos\intelliPos\venv\lib\site-packages\django\core\handlers\base.py", line 181, in _get_response
    response = wrapped_callback(request, *callback_args, **callback_kwargs)
  File "C:\Users\takud\OneDrive\Documents\Development\Intelli-Pos\intelliPos\venv\lib\site-packages\django\views\decorators\csrf.py", line 54, in wrapped_view
    return view_func(*args, **kwargs)
  File "C:\Users\takud\OneDrive\Documents\Development\Intelli-Pos\intelliPos\venv\lib\site-packages\django\views\generic\base.py", line 70, in view
    return self.dispatch(request, *args, **kwargs)
  File "C:\Users\takud\OneDrive\Documents\Development\Intelli-Pos\intelliPos\venv\lib\site-packages\rest_framework\views.py", line 511, in dispatch
    self.response = self.finalize_response(request, response, *args, **kwargs)
  File "C:\Users\takud\OneDrive\Documents\Development\Intelli-Pos\intelliPos\venv\lib\site-packages\rest_framework\views.py", line 426, in finalize_response
    % type(response)
AssertionError: Expected a `Response`, `HttpResponse` or `HttpStreamingResponse` to be returned from the view, but received a `<class 'dict'>`
"GET /api/get_dek/?key_name=token_key HTTP/1.1" 500 85100
Internal Server Error: /api/get_dek/
Traceback (most recent call last):
  File "C:\Users\takud\OneDrive\Documents\Development\Intelli-Pos\intelliPos\venv\lib\site-packages\django\core\handlers\exception.py", line 47, in inner
    response = get_response(request)
  File "C:\Users\takud\OneDrive\Documents\Development\Intelli-Pos\intelliPos\venv\lib\site-packages\django\core\handlers\base.py", line 181, in _get_response
    response = wrapped_callback(request, *callback_args, **callback_kwargs)
  File "C:\Users\takud\OneDrive\Documents\Development\Intelli-Pos\intelliPos\venv\lib\site-packages\django\views\decorators\csrf.py", line 54, in wrapped_view
    return view_func(*args, **kwargs)
  File "C:\Users\takud\OneDrive\Documents\Development\Intelli-Pos\intelliPos\venv\lib\site-packages\django\views\generic\base.py", line 70, in view
    return self.dispatch(request, *args, **kwargs)
  File "C:\Users\takud\OneDrive\Documents\Development\Intelli-Pos\intelliPos\venv\lib\site-packages\rest_framework\views.py", line 509, in dispatch
    response = self.handle_exception(exc)
  File "C:\Users\takud\OneDrive\Documents\Development\Intelli-Pos\intelliPos\venv\lib\site-packages\rest_framework\views.py", line 469, in handle_exception
    self.raise_uncaught_exception(exc)
  File "C:\Users\takud\OneDrive\Documents\Development\Intelli-Pos\intelliPos\venv\lib\site-packages\rest_framework\views.py", line 480, in raise_uncaught_exception
    raise exc
  File "C:\Users\takud\OneDrive\Documents\Development\Intelli-Pos\intelliPos\venv\lib\site-packages\rest_framework\views.py", line 506, in dispatch
    response = handler(request, *args, **kwargs)
  File "C:\Users\takud\OneDrive\Documents\Development\Intelli-Pos\intelliPos\api\views.py", line 53, in get
    access_token = data['access_token']
KeyError: 'access_token'
"GET /api/get_dek/?key_name=token_key HTTP/1.1" 500 99376
Internal Server Error: /api/get_dek/
Traceback (most recent call last):
  File "C:\Users\takud\OneDrive\Documents\Development\Intelli-Pos\intelliPos\venv\lib\site-packages\django\core\handlers\exception.py", line 47, in inner
    response = get_response(request)
  File "C:\Users\takud\OneDrive\Documents\Development\Intelli-Pos\intelliPos\venv\lib\site-packages\django\core\handlers\base.py", line 181, in _get_response
    response = wrapped_callback(request, *callback_args, **callback_kwargs)
  File "C:\Users\takud\OneDrive\Documents\Development\Intelli-Pos\intelliPos\venv\lib\site-packages\django\views\decorators\csrf.py", line 54, in wrapped_view
    return view_func(*args, **kwargs)
  File "C:\Users\takud\OneDrive\Documents\Development\Intelli-Pos\intelliPos\venv\lib\site-packages\django\views\generic\base.py", line 70, in view
    return self.dispatch(request, *args, **kwargs)
  File "C:\Users\takud\OneDrive\Documents\Development\Intelli-Pos\intelliPos\venv\lib\site-packages\rest_framework\views.py", line 509, in dispatch
    response = self.handle_exception(exc)
  File "C:\Users\takud\OneDrive\Documents\Development\Intelli-Pos\intelliPos\venv\lib\site-packages\rest_framework\views.py", line 469, in handle_exception
    self.raise_uncaught_exception(exc)
  File "C:\Users\takud\OneDrive\Documents\Development\Intelli-Pos\intelliPos\venv\lib\site-packages\rest_framework\views.py", line 480, in raise_uncaught_exception
    raise exc
  File "C:\Users\takud\OneDrive\Documents\Development\Intelli-Pos\intelliPos\venv\lib\site-packages\rest_framework\views.py", line 506, in dispatch
    response = handler(request, *args, **kwargs)
  File "C:\Users\takud\OneDrive\Documents\Development\Intelli-Pos\intelliPos\api\views.py", line 59, in get
    return JsonResponse(status=200, data={'success':success, 'message':message})
  File "C:\Users\takud\OneDrive\Documents\Development\Intelli-Pos\intelliPos\venv\lib\site-packages\django\http\response.py", line 567, in __init__
    data = json.dumps(data, cls=encoder, **json_dumps_params)
  File "c:\users\takud\appdata\local\programs\python\python37\lib\json\__init__.py", line 238, in dumps
    **kw).encode(obj)
  File "c:\users\takud\appdata\local\programs\python\python37\lib\json\encoder.py", line 199, in encode
    chunks = self.iterencode(o, _one_shot=True)
  File "c:\users\takud\appdata\local\programs\python\python37\lib\json\encoder.py", line 257, in iterencode
    return _iterencode(o, 0)
  File "C:\Users\takud\OneDrive\Documents\Development\Intelli-Pos\intelliPos\venv\lib\site-packages\django\core\serializers\json.py", line 105, in default
    return super().default(o)
  File "c:\users\takud\appdata\local\programs\python\python37\lib\json\encoder.py", line 179, in default
    raise TypeError(f'Object of type {o.__class__.__name__} '
TypeError: Object of type bytes is not JSON serializable
"GET /api/get_dek/?key_name=token_key HTTP/1.1" 500 126244
Method Not Allowed: /api/register/
"GET /api/register/ HTTP/1.1" 405 40
Internal Server Error: /api/register
Traceback (most recent call last):
  File "C:\Users\takud\OneDrive\Documents\Development\Intelli-Pos\intelliPos\venv\lib\site-packages\django\core\handlers\exception.py", line 47, in inner
    response = get_response(request)
  File "C:\Users\takud\OneDrive\Documents\Development\Intelli-Pos\intelliPos\venv\lib\site-packages\django\utils\deprecation.py", line 113, in __call__
    response = self.process_request(request)
  File "C:\Users\takud\OneDrive\Documents\Development\Intelli-Pos\intelliPos\venv\lib\site-packages\django\middleware\common.py", line 54, in process_request
    path = self.get_full_path_with_slash(request)
  File "C:\Users\takud\OneDrive\Documents\Development\Intelli-Pos\intelliPos\venv\lib\site-packages\django\middleware\common.py", line 94, in get_full_path_with_slash
    'url': request.get_host() + new_path,
RuntimeError: You called this URL via POST, but the URL doesn't end in a slash and you have APPEND_SLASH set. Django can't redirect to the slash URL while maintaining POST data. Change your form to point to 127.0.0.1:8000/api/register/ (note the trailing slash), or set APPEND_SLASH=False in your Django settings.
"POST /api/register HTTP/1.1" 500 75537
Bad Request: /api/register/
"POST /api/register/ HTTP/1.1" 400 73
Bad Request: /api/register/
"POST /api/register/ HTTP/1.1" 400 73
Bad Request: /api/register/
"POST /api/register/ HTTP/1.1" 400 73
Bad Request: /api/register/
"POST /api/register/ HTTP/1.1" 400 73
Bad Request: /api/register/
"POST /api/register/ HTTP/1.1" 400 73
Bad Request: /api/register/
"POST /api/register/ HTTP/1.1" 400 73
Internal Server Error: /api/register/
Traceback (most recent call last):
  File "C:\Users\takud\OneDrive\Documents\Development\Intelli-Pos\intelliPos\venv\lib\site-packages\django\core\handlers\exception.py", line 47, in inner
    response = get_response(request)
  File "C:\Users\takud\OneDrive\Documents\Development\Intelli-Pos\intelliPos\venv\lib\site-packages\django\core\handlers\base.py", line 181, in _get_response
    response = wrapped_callback(request, *callback_args, **callback_kwargs)
  File "C:\Users\takud\OneDrive\Documents\Development\Intelli-Pos\intelliPos\venv\lib\site-packages\django\views\decorators\csrf.py", line 54, in wrapped_view
    return view_func(*args, **kwargs)
  File "C:\Users\takud\OneDrive\Documents\Development\Intelli-Pos\intelliPos\venv\lib\site-packages\django\views\generic\base.py", line 70, in view
    return self.dispatch(request, *args, **kwargs)
  File "C:\Users\takud\OneDrive\Documents\Development\Intelli-Pos\intelliPos\venv\lib\site-packages\rest_framework\views.py", line 509, in dispatch
    response = self.handle_exception(exc)
  File "C:\Users\takud\OneDrive\Documents\Development\Intelli-Pos\intelliPos\venv\lib\site-packages\rest_framework\views.py", line 469, in handle_exception
    self.raise_uncaught_exception(exc)
  File "C:\Users\takud\OneDrive\Documents\Development\Intelli-Pos\intelliPos\venv\lib\site-packages\rest_framework\views.py", line 480, in raise_uncaught_exception
    raise exc
  File "C:\Users\takud\OneDrive\Documents\Development\Intelli-Pos\intelliPos\venv\lib\site-packages\rest_framework\views.py", line 506, in dispatch
    response = handler(request, *args, **kwargs)
  File "C:\Users\takud\OneDrive\Documents\Development\Intelli-Pos\intelliPos\api\views.py", line 70, in post
    print(request.body.json())
AttributeError: 'bytes' object has no attribute 'json'
"POST /api/register/ HTTP/1.1" 500 98120
Internal Server Error: /api/register/
Traceback (most recent call last):
  File "C:\Users\takud\OneDrive\Documents\Development\Intelli-Pos\intelliPos\venv\lib\site-packages\django\core\handlers\exception.py", line 47, in inner
    response = get_response(request)
  File "C:\Users\takud\OneDrive\Documents\Development\Intelli-Pos\intelliPos\venv\lib\site-packages\django\core\handlers\base.py", line 181, in _get_response
    response = wrapped_callback(request, *callback_args, **callback_kwargs)
  File "C:\Users\takud\OneDrive\Documents\Development\Intelli-Pos\intelliPos\venv\lib\site-packages\django\views\decorators\csrf.py", line 54, in wrapped_view
    return view_func(*args, **kwargs)
  File "C:\Users\takud\OneDrive\Documents\Development\Intelli-Pos\intelliPos\venv\lib\site-packages\django\views\generic\base.py", line 70, in view
    return self.dispatch(request, *args, **kwargs)
  File "C:\Users\takud\OneDrive\Documents\Development\Intelli-Pos\intelliPos\venv\lib\site-packages\rest_framework\views.py", line 509, in dispatch
    response = self.handle_exception(exc)
  File "C:\Users\takud\OneDrive\Documents\Development\Intelli-Pos\intelliPos\venv\lib\site-packages\rest_framework\views.py", line 469, in handle_exception
    self.raise_uncaught_exception(exc)
  File "C:\Users\takud\OneDrive\Documents\Development\Intelli-Pos\intelliPos\venv\lib\site-packages\rest_framework\views.py", line 480, in raise_uncaught_exception
    raise exc
  File "C:\Users\takud\OneDrive\Documents\Development\Intelli-Pos\intelliPos\venv\lib\site-packages\rest_framework\views.py", line 506, in dispatch
    response = handler(request, *args, **kwargs)
  File "C:\Users\takud\OneDrive\Documents\Development\Intelli-Pos\intelliPos\api\views.py", line 70, in post
    print(request.body.json())
AttributeError: 'bytes' object has no attribute 'json'
"POST /api/register/ HTTP/1.1" 500 98120
Bad Request: /api/register/
"POST /api/register/ HTTP/1.1" 400 73
Internal Server Error: /api/register/
Traceback (most recent call last):
  File "C:\Users\takud\OneDrive\Documents\Development\Intelli-Pos\intelliPos\venv\lib\site-packages\django\core\handlers\exception.py", line 47, in inner
    response = get_response(request)
  File "C:\Users\takud\OneDrive\Documents\Development\Intelli-Pos\intelliPos\venv\lib\site-packages\django\core\handlers\base.py", line 181, in _get_response
    response = wrapped_callback(request, *callback_args, **callback_kwargs)
  File "C:\Users\takud\OneDrive\Documents\Development\Intelli-Pos\intelliPos\venv\lib\site-packages\django\views\decorators\csrf.py", line 54, in wrapped_view
    return view_func(*args, **kwargs)
  File "C:\Users\takud\OneDrive\Documents\Development\Intelli-Pos\intelliPos\venv\lib\site-packages\django\views\generic\base.py", line 70, in view
    return self.dispatch(request, *args, **kwargs)
  File "C:\Users\takud\OneDrive\Documents\Development\Intelli-Pos\intelliPos\venv\lib\site-packages\rest_framework\views.py", line 509, in dispatch
    response = self.handle_exception(exc)
  File "C:\Users\takud\OneDrive\Documents\Development\Intelli-Pos\intelliPos\venv\lib\site-packages\rest_framework\views.py", line 469, in handle_exception
    self.raise_uncaught_exception(exc)
  File "C:\Users\takud\OneDrive\Documents\Development\Intelli-Pos\intelliPos\venv\lib\site-packages\rest_framework\views.py", line 480, in raise_uncaught_exception
    raise exc
  File "C:\Users\takud\OneDrive\Documents\Development\Intelli-Pos\intelliPos\venv\lib\site-packages\rest_framework\views.py", line 506, in dispatch
    response = handler(request, *args, **kwargs)
  File "C:\Users\takud\OneDrive\Documents\Development\Intelli-Pos\intelliPos\api\views.py", line 71, in post
    data = JSONParser().parse(request.data)
  File "C:\Users\takud\OneDrive\Documents\Development\Intelli-Pos\intelliPos\venv\lib\site-packages\rest_framework\parsers.py", line 65, in parse
    return json.load(decoded_stream, parse_constant=parse_constant)
  File "C:\Users\takud\OneDrive\Documents\Development\Intelli-Pos\intelliPos\venv\lib\site-packages\rest_framework\utils\json.py", line 31, in load
    return json.load(*args, **kwargs)
  File "c:\users\takud\appdata\local\programs\python\python37\lib\json\__init__.py", line 293, in load
    return loads(fp.read(),
  File "c:\users\takud\appdata\local\programs\python\python37\lib\codecs.py", line 496, in read
    newdata = self.stream.read()
AttributeError: 'QueryDict' object has no attribute 'read'
"POST /api/register/ HTTP/1.1" 500 116202
Internal Server Error: /api/register/
Traceback (most recent call last):
  File "C:\Users\takud\OneDrive\Documents\Development\Intelli-Pos\intelliPos\venv\lib\site-packages\django\core\handlers\exception.py", line 47, in inner
    response = get_response(request)
  File "C:\Users\takud\OneDrive\Documents\Development\Intelli-Pos\intelliPos\venv\lib\site-packages\django\core\handlers\base.py", line 181, in _get_response
    response = wrapped_callback(request, *callback_args, **callback_kwargs)
  File "C:\Users\takud\OneDrive\Documents\Development\Intelli-Pos\intelliPos\venv\lib\site-packages\django\views\decorators\csrf.py", line 54, in wrapped_view
    return view_func(*args, **kwargs)
  File "C:\Users\takud\OneDrive\Documents\Development\Intelli-Pos\intelliPos\venv\lib\site-packages\django\views\generic\base.py", line 70, in view
    return self.dispatch(request, *args, **kwargs)
  File "C:\Users\takud\OneDrive\Documents\Development\Intelli-Pos\intelliPos\venv\lib\site-packages\rest_framework\views.py", line 509, in dispatch
    response = self.handle_exception(exc)
  File "C:\Users\takud\OneDrive\Documents\Development\Intelli-Pos\intelliPos\venv\lib\site-packages\rest_framework\views.py", line 469, in handle_exception
    self.raise_uncaught_exception(exc)
  File "C:\Users\takud\OneDrive\Documents\Development\Intelli-Pos\intelliPos\venv\lib\site-packages\rest_framework\views.py", line 480, in raise_uncaught_exception
    raise exc
  File "C:\Users\takud\OneDrive\Documents\Development\Intelli-Pos\intelliPos\venv\lib\site-packages\rest_framework\views.py", line 506, in dispatch
    response = handler(request, *args, **kwargs)
  File "C:\Users\takud\OneDrive\Documents\Development\Intelli-Pos\intelliPos\api\views.py", line 71, in post
    print(JSONParser().parse(request.data))
  File "C:\Users\takud\OneDrive\Documents\Development\Intelli-Pos\intelliPos\venv\lib\site-packages\rest_framework\parsers.py", line 65, in parse
    return json.load(decoded_stream, parse_constant=parse_constant)
  File "C:\Users\takud\OneDrive\Documents\Development\Intelli-Pos\intelliPos\venv\lib\site-packages\rest_framework\utils\json.py", line 31, in load
    return json.load(*args, **kwargs)
  File "c:\users\takud\appdata\local\programs\python\python37\lib\json\__init__.py", line 293, in load
    return loads(fp.read(),
  File "c:\users\takud\appdata\local\programs\python\python37\lib\codecs.py", line 496, in read
    newdata = self.stream.read()
AttributeError: 'QueryDict' object has no attribute 'read'
"POST /api/register/ HTTP/1.1" 500 116249
Not Found: /reset-password
"GET /reset-password HTTP/1.1" 404 2089
Not Found: /reset-password/
"GET /reset-password/ HTTP/1.1" 404 2092
Internal Server Error: /api/reset-password/
Traceback (most recent call last):
  File "C:\Users\takud\OneDrive\Documents\Development\Intelli-Pos\intelliPos\venv\lib\site-packages\django\core\handlers\exception.py", line 47, in inner
    response = get_response(request)
  File "C:\Users\takud\OneDrive\Documents\Development\Intelli-Pos\intelliPos\venv\lib\site-packages\django\core\handlers\base.py", line 181, in _get_response
    response = wrapped_callback(request, *callback_args, **callback_kwargs)
  File "C:\Users\takud\OneDrive\Documents\Development\Intelli-Pos\intelliPos\venv\lib\site-packages\django\views\decorators\csrf.py", line 54, in wrapped_view
    return view_func(*args, **kwargs)
  File "C:\Users\takud\OneDrive\Documents\Development\Intelli-Pos\intelliPos\venv\lib\site-packages\django\views\generic\base.py", line 70, in view
    return self.dispatch(request, *args, **kwargs)
  File "C:\Users\takud\OneDrive\Documents\Development\Intelli-Pos\intelliPos\venv\lib\site-packages\rest_framework\views.py", line 509, in dispatch
    response = self.handle_exception(exc)
  File "C:\Users\takud\OneDrive\Documents\Development\Intelli-Pos\intelliPos\venv\lib\site-packages\rest_framework\views.py", line 469, in handle_exception
    self.raise_uncaught_exception(exc)
  File "C:\Users\takud\OneDrive\Documents\Development\Intelli-Pos\intelliPos\venv\lib\site-packages\rest_framework\views.py", line 480, in raise_uncaught_exception
    raise exc
  File "C:\Users\takud\OneDrive\Documents\Development\Intelli-Pos\intelliPos\venv\lib\site-packages\rest_framework\views.py", line 506, in dispatch
    response = handler(request, *args, **kwargs)
TypeError: get() takes 1 positional argument but 2 were given
"GET /api/reset-password/ HTTP/1.1" 500 93191
Internal Server Error: /api/reset-password/
Traceback (most recent call last):
  File "C:\Users\takud\OneDrive\Documents\Development\Intelli-Pos\intelliPos\venv\lib\site-packages\django\core\handlers\exception.py", line 47, in inner
    response = get_response(request)
  File "C:\Users\takud\OneDrive\Documents\Development\Intelli-Pos\intelliPos\venv\lib\site-packages\django\core\handlers\base.py", line 181, in _get_response
    response = wrapped_callback(request, *callback_args, **callback_kwargs)
  File "C:\Users\takud\OneDrive\Documents\Development\Intelli-Pos\intelliPos\venv\lib\site-packages\django\views\decorators\csrf.py", line 54, in wrapped_view
    return view_func(*args, **kwargs)
  File "C:\Users\takud\OneDrive\Documents\Development\Intelli-Pos\intelliPos\venv\lib\site-packages\django\views\generic\base.py", line 70, in view
    return self.dispatch(request, *args, **kwargs)
  File "C:\Users\takud\OneDrive\Documents\Development\Intelli-Pos\intelliPos\venv\lib\site-packages\rest_framework\views.py", line 509, in dispatch
    response = self.handle_exception(exc)
  File "C:\Users\takud\OneDrive\Documents\Development\Intelli-Pos\intelliPos\venv\lib\site-packages\rest_framework\views.py", line 469, in handle_exception
    self.raise_uncaught_exception(exc)
  File "C:\Users\takud\OneDrive\Documents\Development\Intelli-Pos\intelliPos\venv\lib\site-packages\rest_framework\views.py", line 480, in raise_uncaught_exception
    raise exc
  File "C:\Users\takud\OneDrive\Documents\Development\Intelli-Pos\intelliPos\venv\lib\site-packages\rest_framework\views.py", line 506, in dispatch
    response = handler(request, *args, **kwargs)
  File "C:\Users\takud\OneDrive\Documents\Development\Intelli-Pos\intelliPos\api\views.py", line 71, in get
    otp = os.random(6)
AttributeError: module 'os' has no attribute 'random'
"GET /api/reset-password/ HTTP/1.1" 500 97934
Internal Server Error: /api/reset-password/
Traceback (most recent call last):
  File "C:\Users\takud\OneDrive\Documents\Development\Intelli-Pos\intelliPos\venv\lib\site-packages\django\core\handlers\exception.py", line 47, in inner
    response = get_response(request)
  File "C:\Users\takud\OneDrive\Documents\Development\Intelli-Pos\intelliPos\venv\lib\site-packages\django\core\handlers\base.py", line 181, in _get_response
    response = wrapped_callback(request, *callback_args, **callback_kwargs)
  File "C:\Users\takud\OneDrive\Documents\Development\Intelli-Pos\intelliPos\venv\lib\site-packages\django\views\decorators\csrf.py", line 54, in wrapped_view
    return view_func(*args, **kwargs)
  File "C:\Users\takud\OneDrive\Documents\Development\Intelli-Pos\intelliPos\venv\lib\site-packages\django\views\generic\base.py", line 70, in view
    return self.dispatch(request, *args, **kwargs)
  File "C:\Users\takud\OneDrive\Documents\Development\Intelli-Pos\intelliPos\venv\lib\site-packages\rest_framework\views.py", line 509, in dispatch
    response = self.handle_exception(exc)
  File "C:\Users\takud\OneDrive\Documents\Development\Intelli-Pos\intelliPos\venv\lib\site-packages\rest_framework\views.py", line 469, in handle_exception
    self.raise_uncaught_exception(exc)
  File "C:\Users\takud\OneDrive\Documents\Development\Intelli-Pos\intelliPos\venv\lib\site-packages\rest_framework\views.py", line 480, in raise_uncaught_exception
    raise exc
  File "C:\Users\takud\OneDrive\Documents\Development\Intelli-Pos\intelliPos\venv\lib\site-packages\rest_framework\views.py", line 506, in dispatch
    response = handler(request, *args, **kwargs)
  File "C:\Users\takud\OneDrive\Documents\Development\Intelli-Pos\intelliPos\api\views.py", line 71, in get
    otp = random.randint(6)
TypeError: randint() missing 1 required positional argument: 'b'
"GET /api/reset-password/ HTTP/1.1" 500 97940
Internal Server Error: /api/reset-password/
Traceback (most recent call last):
  File "C:\Users\takud\OneDrive\Documents\Development\Intelli-Pos\intelliPos\venv\lib\site-packages\django\core\handlers\exception.py", line 47, in inner
    response = get_response(request)
  File "C:\Users\takud\OneDrive\Documents\Development\Intelli-Pos\intelliPos\venv\lib\site-packages\django\core\handlers\base.py", line 181, in _get_response
    response = wrapped_callback(request, *callback_args, **callback_kwargs)
  File "C:\Users\takud\OneDrive\Documents\Development\Intelli-Pos\intelliPos\venv\lib\site-packages\django\views\decorators\csrf.py", line 54, in wrapped_view
    return view_func(*args, **kwargs)
  File "C:\Users\takud\OneDrive\Documents\Development\Intelli-Pos\intelliPos\venv\lib\site-packages\django\views\generic\base.py", line 70, in view
    return self.dispatch(request, *args, **kwargs)
  File "C:\Users\takud\OneDrive\Documents\Development\Intelli-Pos\intelliPos\venv\lib\site-packages\rest_framework\views.py", line 509, in dispatch
    response = self.handle_exception(exc)
  File "C:\Users\takud\OneDrive\Documents\Development\Intelli-Pos\intelliPos\venv\lib\site-packages\rest_framework\views.py", line 469, in handle_exception
    self.raise_uncaught_exception(exc)
  File "C:\Users\takud\OneDrive\Documents\Development\Intelli-Pos\intelliPos\venv\lib\site-packages\rest_framework\views.py", line 480, in raise_uncaught_exception
    raise exc
  File "C:\Users\takud\OneDrive\Documents\Development\Intelli-Pos\intelliPos\venv\lib\site-packages\rest_framework\views.py", line 506, in dispatch
    response = handler(request, *args, **kwargs)
  File "C:\Users\takud\OneDrive\Documents\Development\Intelli-Pos\intelliPos\api\views.py", line 73, in get
    message = "A password reset was initiated for your account. Please Enter the OTP " + otp + " on the mobile app to reset"
TypeError: can only concatenate str (not "int") to str
"GET /api/reset-password/ HTTP/1.1" 500 98208
Internal Server Error: /api/reset-password/
Traceback (most recent call last):
  File "C:\Users\takud\OneDrive\Documents\Development\Intelli-Pos\intelliPos\venv\lib\site-packages\django\core\handlers\exception.py", line 47, in inner
    response = get_response(request)
  File "C:\Users\takud\OneDrive\Documents\Development\Intelli-Pos\intelliPos\venv\lib\site-packages\django\core\handlers\base.py", line 181, in _get_response
    response = wrapped_callback(request, *callback_args, **callback_kwargs)
  File "C:\Users\takud\OneDrive\Documents\Development\Intelli-Pos\intelliPos\venv\lib\site-packages\django\views\decorators\csrf.py", line 54, in wrapped_view
    return view_func(*args, **kwargs)
  File "C:\Users\takud\OneDrive\Documents\Development\Intelli-Pos\intelliPos\venv\lib\site-packages\django\views\generic\base.py", line 70, in view
    return self.dispatch(request, *args, **kwargs)
  File "C:\Users\takud\OneDrive\Documents\Development\Intelli-Pos\intelliPos\venv\lib\site-packages\rest_framework\views.py", line 509, in dispatch
    response = self.handle_exception(exc)
  File "C:\Users\takud\OneDrive\Documents\Development\Intelli-Pos\intelliPos\venv\lib\site-packages\rest_framework\views.py", line 469, in handle_exception
    self.raise_uncaught_exception(exc)
  File "C:\Users\takud\OneDrive\Documents\Development\Intelli-Pos\intelliPos\venv\lib\site-packages\rest_framework\views.py", line 480, in raise_uncaught_exception
    raise exc
  File "C:\Users\takud\OneDrive\Documents\Development\Intelli-Pos\intelliPos\venv\lib\site-packages\rest_framework\views.py", line 506, in dispatch
    response = handler(request, *args, **kwargs)
TypeError: post() takes 1 positional argument but 2 were given
"POST /api/reset-password/ HTTP/1.1" 500 93785
Internal Server Error: /api/reset-password/
Traceback (most recent call last):
  File "C:\Users\takud\OneDrive\Documents\Development\Intelli-Pos\intelliPos\venv\lib\site-packages\django\core\handlers\exception.py", line 47, in inner
    response = get_response(request)
  File "C:\Users\takud\OneDrive\Documents\Development\Intelli-Pos\intelliPos\venv\lib\site-packages\django\core\handlers\base.py", line 181, in _get_response
    response = wrapped_callback(request, *callback_args, **callback_kwargs)
  File "C:\Users\takud\OneDrive\Documents\Development\Intelli-Pos\intelliPos\venv\lib\site-packages\django\views\decorators\csrf.py", line 54, in wrapped_view
    return view_func(*args, **kwargs)
  File "C:\Users\takud\OneDrive\Documents\Development\Intelli-Pos\intelliPos\venv\lib\site-packages\django\views\generic\base.py", line 70, in view
    return self.dispatch(request, *args, **kwargs)
  File "C:\Users\takud\OneDrive\Documents\Development\Intelli-Pos\intelliPos\venv\lib\site-packages\rest_framework\views.py", line 509, in dispatch
    response = self.handle_exception(exc)
  File "C:\Users\takud\OneDrive\Documents\Development\Intelli-Pos\intelliPos\venv\lib\site-packages\rest_framework\views.py", line 469, in handle_exception
    self.raise_uncaught_exception(exc)
  File "C:\Users\takud\OneDrive\Documents\Development\Intelli-Pos\intelliPos\venv\lib\site-packages\rest_framework\views.py", line 480, in raise_uncaught_exception
    raise exc
  File "C:\Users\takud\OneDrive\Documents\Development\Intelli-Pos\intelliPos\venv\lib\site-packages\rest_framework\views.py", line 506, in dispatch
    response = handler(request, *args, **kwargs)
  File "C:\Users\takud\OneDrive\Documents\Development\Intelli-Pos\intelliPos\api\views.py", line 90, in post
    user = User.object.filter(email=email).first()
AttributeError: type object 'User' has no attribute 'object'
"POST /api/reset-password/ HTTP/1.1" 500 98393
Internal Server Error: /api/reset-password/
Traceback (most recent call last):
  File "C:\Users\takud\OneDrive\Documents\Development\Intelli-Pos\intelliPos\venv\lib\site-packages\django\core\handlers\exception.py", line 47, in inner
    response = get_response(request)
  File "C:\Users\takud\OneDrive\Documents\Development\Intelli-Pos\intelliPos\venv\lib\site-packages\django\core\handlers\base.py", line 181, in _get_response
    response = wrapped_callback(request, *callback_args, **callback_kwargs)
  File "C:\Users\takud\OneDrive\Documents\Development\Intelli-Pos\intelliPos\venv\lib\site-packages\django\views\decorators\csrf.py", line 54, in wrapped_view
    return view_func(*args, **kwargs)
  File "C:\Users\takud\OneDrive\Documents\Development\Intelli-Pos\intelliPos\venv\lib\site-packages\django\views\generic\base.py", line 70, in view
    return self.dispatch(request, *args, **kwargs)
  File "C:\Users\takud\OneDrive\Documents\Development\Intelli-Pos\intelliPos\venv\lib\site-packages\rest_framework\views.py", line 509, in dispatch
    response = self.handle_exception(exc)
  File "C:\Users\takud\OneDrive\Documents\Development\Intelli-Pos\intelliPos\venv\lib\site-packages\rest_framework\views.py", line 469, in handle_exception
    self.raise_uncaught_exception(exc)
  File "C:\Users\takud\OneDrive\Documents\Development\Intelli-Pos\intelliPos\venv\lib\site-packages\rest_framework\views.py", line 480, in raise_uncaught_exception
    raise exc
  File "C:\Users\takud\OneDrive\Documents\Development\Intelli-Pos\intelliPos\venv\lib\site-packages\rest_framework\views.py", line 506, in dispatch
    response = handler(request, *args, **kwargs)
  File "C:\Users\takud\OneDrive\Documents\Development\Intelli-Pos\intelliPos\api\views.py", line 101, in post
    if password_used(user, password):
  File "C:\Users\takud\OneDrive\Documents\Development\Intelli-Pos\intelliPos\api\helper_functions.py", line 12, in password_used
    PasswordHistory(user=user, password_hash_1=user.password_hash).save()
AttributeError: 'User' object has no attribute 'password_hash'
"POST /api/reset-password/ HTTP/1.1" 500 102841
Internal Server Error: /api/reset-password/
Traceback (most recent call last):
  File "C:\Users\takud\OneDrive\Documents\Development\Intelli-Pos\intelliPos\venv\lib\site-packages\django\core\handlers\exception.py", line 47, in inner
    response = get_response(request)
  File "C:\Users\takud\OneDrive\Documents\Development\Intelli-Pos\intelliPos\venv\lib\site-packages\django\core\handlers\base.py", line 181, in _get_response
    response = wrapped_callback(request, *callback_args, **callback_kwargs)
  File "C:\Users\takud\OneDrive\Documents\Development\Intelli-Pos\intelliPos\venv\lib\site-packages\django\views\decorators\csrf.py", line 54, in wrapped_view
    return view_func(*args, **kwargs)
  File "C:\Users\takud\OneDrive\Documents\Development\Intelli-Pos\intelliPos\venv\lib\site-packages\django\views\generic\base.py", line 70, in view
    return self.dispatch(request, *args, **kwargs)
  File "C:\Users\takud\OneDrive\Documents\Development\Intelli-Pos\intelliPos\venv\lib\site-packages\rest_framework\views.py", line 509, in dispatch
    response = self.handle_exception(exc)
  File "C:\Users\takud\OneDrive\Documents\Development\Intelli-Pos\intelliPos\venv\lib\site-packages\rest_framework\views.py", line 469, in handle_exception
    self.raise_uncaught_exception(exc)
  File "C:\Users\takud\OneDrive\Documents\Development\Intelli-Pos\intelliPos\venv\lib\site-packages\rest_framework\views.py", line 480, in raise_uncaught_exception
    raise exc
  File "C:\Users\takud\OneDrive\Documents\Development\Intelli-Pos\intelliPos\venv\lib\site-packages\rest_framework\views.py", line 506, in dispatch
    response = handler(request, *args, **kwargs)
  File "C:\Users\takud\OneDrive\Documents\Development\Intelli-Pos\intelliPos\api\views.py", line 101, in post
    if password_used(user, password):
  File "C:\Users\takud\OneDrive\Documents\Development\Intelli-Pos\intelliPos\api\helper_functions.py", line 12, in password_used
    PasswordHistory(user=user, password_hash_1=user.password_hash).save()
AttributeError: 'User' object has no attribute 'password_hash'
"POST /api/reset-password/ HTTP/1.1" 500 102841
Internal Server Error: /api/reset-password/
Traceback (most recent call last):
  File "C:\Users\takud\OneDrive\Documents\Development\Intelli-Pos\intelliPos\venv\lib\site-packages\django\core\handlers\exception.py", line 47, in inner
    response = get_response(request)
  File "C:\Users\takud\OneDrive\Documents\Development\Intelli-Pos\intelliPos\venv\lib\site-packages\django\core\handlers\base.py", line 181, in _get_response
    response = wrapped_callback(request, *callback_args, **callback_kwargs)
  File "C:\Users\takud\OneDrive\Documents\Development\Intelli-Pos\intelliPos\venv\lib\site-packages\django\views\decorators\csrf.py", line 54, in wrapped_view
    return view_func(*args, **kwargs)
  File "C:\Users\takud\OneDrive\Documents\Development\Intelli-Pos\intelliPos\venv\lib\site-packages\django\views\generic\base.py", line 70, in view
    return self.dispatch(request, *args, **kwargs)
  File "C:\Users\takud\OneDrive\Documents\Development\Intelli-Pos\intelliPos\venv\lib\site-packages\rest_framework\views.py", line 509, in dispatch
    response = self.handle_exception(exc)
  File "C:\Users\takud\OneDrive\Documents\Development\Intelli-Pos\intelliPos\venv\lib\site-packages\rest_framework\views.py", line 469, in handle_exception
    self.raise_uncaught_exception(exc)
  File "C:\Users\takud\OneDrive\Documents\Development\Intelli-Pos\intelliPos\venv\lib\site-packages\rest_framework\views.py", line 480, in raise_uncaught_exception
    raise exc
  File "C:\Users\takud\OneDrive\Documents\Development\Intelli-Pos\intelliPos\venv\lib\site-packages\rest_framework\views.py", line 506, in dispatch
    response = handler(request, *args, **kwargs)
  File "C:\Users\takud\OneDrive\Documents\Development\Intelli-Pos\intelliPos\api\views.py", line 101, in post
    if password_used(user, password):
  File "C:\Users\takud\OneDrive\Documents\Development\Intelli-Pos\intelliPos\api\helper_functions.py", line 24, in password_used
    save_to_history(user, history)
  File "C:\Users\takud\OneDrive\Documents\Development\Intelli-Pos\intelliPos\api\helper_functions.py", line 29, in save_to_history
    if history.next_clycle == 1:
AttributeError: 'PasswordHistory' object has no attribute 'next_clycle'
"POST /api/reset-password/ HTTP/1.1" 500 106630
Internal Server Error: /api/reset-password/
Traceback (most recent call last):
  File "C:\Users\takud\OneDrive\Documents\Development\Intelli-Pos\intelliPos\venv\lib\site-packages\django\core\handlers\exception.py", line 47, in inner
    response = get_response(request)
  File "C:\Users\takud\OneDrive\Documents\Development\Intelli-Pos\intelliPos\venv\lib\site-packages\django\core\handlers\base.py", line 181, in _get_response
    response = wrapped_callback(request, *callback_args, **callback_kwargs)
  File "C:\Users\takud\OneDrive\Documents\Development\Intelli-Pos\intelliPos\venv\lib\site-packages\django\views\decorators\csrf.py", line 54, in wrapped_view
    return view_func(*args, **kwargs)
  File "C:\Users\takud\OneDrive\Documents\Development\Intelli-Pos\intelliPos\venv\lib\site-packages\django\views\generic\base.py", line 70, in view
    return self.dispatch(request, *args, **kwargs)
  File "C:\Users\takud\OneDrive\Documents\Development\Intelli-Pos\intelliPos\venv\lib\site-packages\rest_framework\views.py", line 509, in dispatch
    response = self.handle_exception(exc)
  File "C:\Users\takud\OneDrive\Documents\Development\Intelli-Pos\intelliPos\venv\lib\site-packages\rest_framework\views.py", line 469, in handle_exception
    self.raise_uncaught_exception(exc)
  File "C:\Users\takud\OneDrive\Documents\Development\Intelli-Pos\intelliPos\venv\lib\site-packages\rest_framework\views.py", line 480, in raise_uncaught_exception
    raise exc
  File "C:\Users\takud\OneDrive\Documents\Development\Intelli-Pos\intelliPos\venv\lib\site-packages\rest_framework\views.py", line 506, in dispatch
    response = handler(request, *args, **kwargs)
  File "C:\Users\takud\OneDrive\Documents\Development\Intelli-Pos\intelliPos\api\views.py", line 101, in post
    if password_used(user, password):
  File "C:\Users\takud\OneDrive\Documents\Development\Intelli-Pos\intelliPos\api\helper_functions.py", line 24, in password_used
    save_to_history(user, history)
  File "C:\Users\takud\OneDrive\Documents\Development\Intelli-Pos\intelliPos\api\helper_functions.py", line 29, in save_to_history
    if history.next_clycle == 1:
AttributeError: 'PasswordHistory' object has no attribute 'next_clycle'
"POST /api/reset-password/ HTTP/1.1" 500 106630
Internal Server Error: /api/reset-password/
Traceback (most recent call last):
  File "C:\Users\takud\OneDrive\Documents\Development\Intelli-Pos\intelliPos\venv\lib\site-packages\django\core\handlers\exception.py", line 47, in inner
    response = get_response(request)
  File "C:\Users\takud\OneDrive\Documents\Development\Intelli-Pos\intelliPos\venv\lib\site-packages\django\core\handlers\base.py", line 181, in _get_response
    response = wrapped_callback(request, *callback_args, **callback_kwargs)
  File "C:\Users\takud\OneDrive\Documents\Development\Intelli-Pos\intelliPos\venv\lib\site-packages\django\views\decorators\csrf.py", line 54, in wrapped_view
    return view_func(*args, **kwargs)
  File "C:\Users\takud\OneDrive\Documents\Development\Intelli-Pos\intelliPos\venv\lib\site-packages\django\views\generic\base.py", line 70, in view
    return self.dispatch(request, *args, **kwargs)
  File "C:\Users\takud\OneDrive\Documents\Development\Intelli-Pos\intelliPos\venv\lib\site-packages\rest_framework\views.py", line 509, in dispatch
    response = self.handle_exception(exc)
  File "C:\Users\takud\OneDrive\Documents\Development\Intelli-Pos\intelliPos\venv\lib\site-packages\rest_framework\views.py", line 469, in handle_exception
    self.raise_uncaught_exception(exc)
  File "C:\Users\takud\OneDrive\Documents\Development\Intelli-Pos\intelliPos\venv\lib\site-packages\rest_framework\views.py", line 480, in raise_uncaught_exception
    raise exc
  File "C:\Users\takud\OneDrive\Documents\Development\Intelli-Pos\intelliPos\venv\lib\site-packages\rest_framework\views.py", line 506, in dispatch
    response = handler(request, *args, **kwargs)
  File "C:\Users\takud\OneDrive\Documents\Development\Intelli-Pos\intelliPos\api\views.py", line 101, in post
    if password_used(user, password):
  File "C:\Users\takud\OneDrive\Documents\Development\Intelli-Pos\intelliPos\api\helper_functions.py", line 24, in password_used
    save_to_history(user, history)
  File "C:\Users\takud\OneDrive\Documents\Development\Intelli-Pos\intelliPos\api\helper_functions.py", line 32, in save_to_history
    elif history.next_clycle == 1:
AttributeError: 'PasswordHistory' object has no attribute 'next_clycle'
"POST /api/reset-password/ HTTP/1.1" 500 106642
Internal Server Error: /api/reset-password/
Traceback (most recent call last):
  File "C:\Users\takud\OneDrive\Documents\Development\Intelli-Pos\intelliPos\venv\lib\site-packages\django\core\handlers\exception.py", line 47, in inner
    response = get_response(request)
  File "C:\Users\takud\OneDrive\Documents\Development\Intelli-Pos\intelliPos\venv\lib\site-packages\django\core\handlers\base.py", line 181, in _get_response
    response = wrapped_callback(request, *callback_args, **callback_kwargs)
  File "C:\Users\takud\OneDrive\Documents\Development\Intelli-Pos\intelliPos\venv\lib\site-packages\django\views\decorators\csrf.py", line 54, in wrapped_view
    return view_func(*args, **kwargs)
  File "C:\Users\takud\OneDrive\Documents\Development\Intelli-Pos\intelliPos\venv\lib\site-packages\django\views\generic\base.py", line 70, in view
    return self.dispatch(request, *args, **kwargs)
  File "C:\Users\takud\OneDrive\Documents\Development\Intelli-Pos\intelliPos\venv\lib\site-packages\rest_framework\views.py", line 509, in dispatch
    response = self.handle_exception(exc)
  File "C:\Users\takud\OneDrive\Documents\Development\Intelli-Pos\intelliPos\venv\lib\site-packages\rest_framework\views.py", line 469, in handle_exception
    self.raise_uncaught_exception(exc)
  File "C:\Users\takud\OneDrive\Documents\Development\Intelli-Pos\intelliPos\venv\lib\site-packages\rest_framework\views.py", line 480, in raise_uncaught_exception
    raise exc
  File "C:\Users\takud\OneDrive\Documents\Development\Intelli-Pos\intelliPos\venv\lib\site-packages\rest_framework\views.py", line 506, in dispatch
    response = handler(request, *args, **kwargs)
  File "C:\Users\takud\OneDrive\Documents\Development\Intelli-Pos\intelliPos\api\views.py", line 101, in post
    if password_used(user, password):
  File "C:\Users\takud\OneDrive\Documents\Development\Intelli-Pos\intelliPos\api\helper_functions.py", line 26, in password_used
    save_to_history(user, history)
  File "C:\Users\takud\OneDrive\Documents\Development\Intelli-Pos\intelliPos\api\helper_functions.py", line 37, in save_to_history
    elif history.next_clycle == 3:
AttributeError: 'PasswordHistory' object has no attribute 'next_clycle'
"POST /api/reset-password/ HTTP/1.1" 500 106713
Internal Server Error: /api/reset-password/
Traceback (most recent call last):
  File "C:\Users\takud\OneDrive\Documents\Development\Intelli-Pos\intelliPos\venv\lib\site-packages\django\core\handlers\exception.py", line 47, in inner
    response = get_response(request)
  File "C:\Users\takud\OneDrive\Documents\Development\Intelli-Pos\intelliPos\venv\lib\site-packages\django\core\handlers\base.py", line 181, in _get_response
    response = wrapped_callback(request, *callback_args, **callback_kwargs)
  File "C:\Users\takud\OneDrive\Documents\Development\Intelli-Pos\intelliPos\venv\lib\site-packages\django\views\decorators\csrf.py", line 54, in wrapped_view
    return view_func(*args, **kwargs)
  File "C:\Users\takud\OneDrive\Documents\Development\Intelli-Pos\intelliPos\venv\lib\site-packages\django\views\generic\base.py", line 70, in view
    return self.dispatch(request, *args, **kwargs)
  File "C:\Users\takud\OneDrive\Documents\Development\Intelli-Pos\intelliPos\venv\lib\site-packages\rest_framework\views.py", line 509, in dispatch
    response = self.handle_exception(exc)
  File "C:\Users\takud\OneDrive\Documents\Development\Intelli-Pos\intelliPos\venv\lib\site-packages\rest_framework\views.py", line 469, in handle_exception
    self.raise_uncaught_exception(exc)
  File "C:\Users\takud\OneDrive\Documents\Development\Intelli-Pos\intelliPos\venv\lib\site-packages\rest_framework\views.py", line 480, in raise_uncaught_exception
    raise exc
  File "C:\Users\takud\OneDrive\Documents\Development\Intelli-Pos\intelliPos\venv\lib\site-packages\rest_framework\views.py", line 506, in dispatch
    response = handler(request, *args, **kwargs)
  File "C:\Users\takud\OneDrive\Documents\Development\Intelli-Pos\intelliPos\api\views.py", line 101, in post
    if password_used(user, password):
  File "C:\Users\takud\OneDrive\Documents\Development\Intelli-Pos\intelliPos\api\helper_functions.py", line 26, in password_used
    save_to_history(user, history)
  File "C:\Users\takud\OneDrive\Documents\Development\Intelli-Pos\intelliPos\api\helper_functions.py", line 37, in save_to_history
    elif history.next_clycle == 3:
AttributeError: 'PasswordHistory' object has no attribute 'next_clycle'
"POST /api/reset-password/ HTTP/1.1" 500 106712
Internal Server Error: /api/reset-password/
Traceback (most recent call last):
  File "C:\Users\takud\OneDrive\Documents\Development\Intelli-Pos\intelliPos\venv\lib\site-packages\django\core\handlers\exception.py", line 47, in inner
    response = get_response(request)
  File "C:\Users\takud\OneDrive\Documents\Development\Intelli-Pos\intelliPos\venv\lib\site-packages\django\core\handlers\base.py", line 181, in _get_response
    response = wrapped_callback(request, *callback_args, **callback_kwargs)
  File "C:\Users\takud\OneDrive\Documents\Development\Intelli-Pos\intelliPos\venv\lib\site-packages\django\views\decorators\csrf.py", line 54, in wrapped_view
    return view_func(*args, **kwargs)
  File "C:\Users\takud\OneDrive\Documents\Development\Intelli-Pos\intelliPos\venv\lib\site-packages\django\views\generic\base.py", line 70, in view
    return self.dispatch(request, *args, **kwargs)
  File "C:\Users\takud\OneDrive\Documents\Development\Intelli-Pos\intelliPos\venv\lib\site-packages\rest_framework\views.py", line 509, in dispatch
    response = self.handle_exception(exc)
  File "C:\Users\takud\OneDrive\Documents\Development\Intelli-Pos\intelliPos\venv\lib\site-packages\rest_framework\views.py", line 469, in handle_exception
    self.raise_uncaught_exception(exc)
  File "C:\Users\takud\OneDrive\Documents\Development\Intelli-Pos\intelliPos\venv\lib\site-packages\rest_framework\views.py", line 480, in raise_uncaught_exception
    raise exc
  File "C:\Users\takud\OneDrive\Documents\Development\Intelli-Pos\intelliPos\venv\lib\site-packages\rest_framework\views.py", line 506, in dispatch
    response = handler(request, *args, **kwargs)
  File "C:\Users\takud\OneDrive\Documents\Development\Intelli-Pos\intelliPos\api\views.py", line 101, in post
    if password_used(user, password):
  File "C:\Users\takud\OneDrive\Documents\Development\Intelli-Pos\intelliPos\api\helper_functions.py", line 12, in password_used
    if bcrypt.checkpw(new_password, user.password.encode("utf-8")):
  File "C:\Users\takud\OneDrive\Documents\Development\Intelli-Pos\intelliPos\venv\lib\site-packages\bcrypt\__init__.py", line 120, in checkpw
    raise TypeError("Unicode-objects must be encoded before checking")
TypeError: Unicode-objects must be encoded before checking
"POST /api/reset-password/ HTTP/1.1" 500 106784
Internal Server Error: /api/reset-password/
Traceback (most recent call last):
  File "C:\Users\takud\OneDrive\Documents\Development\Intelli-Pos\intelliPos\venv\lib\site-packages\django\core\handlers\exception.py", line 47, in inner
    response = get_response(request)
  File "C:\Users\takud\OneDrive\Documents\Development\Intelli-Pos\intelliPos\venv\lib\site-packages\django\core\handlers\base.py", line 181, in _get_response
    response = wrapped_callback(request, *callback_args, **callback_kwargs)
  File "C:\Users\takud\OneDrive\Documents\Development\Intelli-Pos\intelliPos\venv\lib\site-packages\django\views\decorators\csrf.py", line 54, in wrapped_view
    return view_func(*args, **kwargs)
  File "C:\Users\takud\OneDrive\Documents\Development\Intelli-Pos\intelliPos\venv\lib\site-packages\django\views\generic\base.py", line 70, in view
    return self.dispatch(request, *args, **kwargs)
  File "C:\Users\takud\OneDrive\Documents\Development\Intelli-Pos\intelliPos\venv\lib\site-packages\rest_framework\views.py", line 509, in dispatch
    response = self.handle_exception(exc)
  File "C:\Users\takud\OneDrive\Documents\Development\Intelli-Pos\intelliPos\venv\lib\site-packages\rest_framework\views.py", line 469, in handle_exception
    self.raise_uncaught_exception(exc)
  File "C:\Users\takud\OneDrive\Documents\Development\Intelli-Pos\intelliPos\venv\lib\site-packages\rest_framework\views.py", line 480, in raise_uncaught_exception
    raise exc
  File "C:\Users\takud\OneDrive\Documents\Development\Intelli-Pos\intelliPos\venv\lib\site-packages\rest_framework\views.py", line 506, in dispatch
    response = handler(request, *args, **kwargs)
  File "C:\Users\takud\OneDrive\Documents\Development\Intelli-Pos\intelliPos\api\views.py", line 101, in post
    if password_used(user, password):
  File "C:\Users\takud\OneDrive\Documents\Development\Intelli-Pos\intelliPos\api\helper_functions.py", line 12, in password_used
    if bcrypt.checkpw(new_password.encode("utf-8"), user.password.encode("utf-8")):
  File "C:\Users\takud\OneDrive\Documents\Development\Intelli-Pos\intelliPos\venv\lib\site-packages\bcrypt\__init__.py", line 127, in checkpw
    ret = hashpw(password, hashed_password)
  File "C:\Users\takud\OneDrive\Documents\Development\Intelli-Pos\intelliPos\venv\lib\site-packages\bcrypt\__init__.py", line 105, in hashpw
    raise ValueError("Invalid salt")
ValueError: Invalid salt
"POST /api/reset-password/ HTTP/1.1" 500 111378
Internal Server Error: /api/reset-password/
Traceback (most recent call last):
  File "C:\Users\takud\OneDrive\Documents\Development\Intelli-Pos\intelliPos\venv\lib\site-packages\django\core\handlers\exception.py", line 47, in inner
    response = get_response(request)
  File "C:\Users\takud\OneDrive\Documents\Development\Intelli-Pos\intelliPos\venv\lib\site-packages\django\core\handlers\base.py", line 181, in _get_response
    response = wrapped_callback(request, *callback_args, **callback_kwargs)
  File "C:\Users\takud\OneDrive\Documents\Development\Intelli-Pos\intelliPos\venv\lib\site-packages\django\views\decorators\csrf.py", line 54, in wrapped_view
    return view_func(*args, **kwargs)
  File "C:\Users\takud\OneDrive\Documents\Development\Intelli-Pos\intelliPos\venv\lib\site-packages\django\views\generic\base.py", line 70, in view
    return self.dispatch(request, *args, **kwargs)
  File "C:\Users\takud\OneDrive\Documents\Development\Intelli-Pos\intelliPos\venv\lib\site-packages\rest_framework\views.py", line 509, in dispatch
    response = self.handle_exception(exc)
  File "C:\Users\takud\OneDrive\Documents\Development\Intelli-Pos\intelliPos\venv\lib\site-packages\rest_framework\views.py", line 469, in handle_exception
    self.raise_uncaught_exception(exc)
  File "C:\Users\takud\OneDrive\Documents\Development\Intelli-Pos\intelliPos\venv\lib\site-packages\rest_framework\views.py", line 480, in raise_uncaught_exception
    raise exc
  File "C:\Users\takud\OneDrive\Documents\Development\Intelli-Pos\intelliPos\venv\lib\site-packages\rest_framework\views.py", line 506, in dispatch
    response = handler(request, *args, **kwargs)
  File "C:\Users\takud\OneDrive\Documents\Development\Intelli-Pos\intelliPos\api\views.py", line 100, in post
    if password_used(user, data.encode('utf8')):
  File "C:\Users\takud\OneDrive\Documents\Development\Intelli-Pos\intelliPos\api\helper_functions.py", line 12, in password_used
    if bcrypt.checkpw(new_password, user.password.encode("utf-8")):
  File "C:\Users\takud\OneDrive\Documents\Development\Intelli-Pos\intelliPos\venv\lib\site-packages\bcrypt\__init__.py", line 127, in checkpw
    ret = hashpw(password, hashed_password)
  File "C:\Users\takud\OneDrive\Documents\Development\Intelli-Pos\intelliPos\venv\lib\site-packages\bcrypt\__init__.py", line 105, in hashpw
    raise ValueError("Invalid salt")
ValueError: Invalid salt
"POST /api/reset-password/ HTTP/1.1" 500 110914
Internal Server Error: /api/reset-password/
Traceback (most recent call last):
  File "C:\Users\takud\OneDrive\Documents\Development\Intelli-Pos\intelliPos\venv\lib\site-packages\django\core\handlers\exception.py", line 47, in inner
    response = get_response(request)
  File "C:\Users\takud\OneDrive\Documents\Development\Intelli-Pos\intelliPos\venv\lib\site-packages\django\core\handlers\base.py", line 181, in _get_response
    response = wrapped_callback(request, *callback_args, **callback_kwargs)
  File "C:\Users\takud\OneDrive\Documents\Development\Intelli-Pos\intelliPos\venv\lib\site-packages\django\views\decorators\csrf.py", line 54, in wrapped_view
    return view_func(*args, **kwargs)
  File "C:\Users\takud\OneDrive\Documents\Development\Intelli-Pos\intelliPos\venv\lib\site-packages\django\views\generic\base.py", line 70, in view
    return self.dispatch(request, *args, **kwargs)
  File "C:\Users\takud\OneDrive\Documents\Development\Intelli-Pos\intelliPos\venv\lib\site-packages\rest_framework\views.py", line 509, in dispatch
    response = self.handle_exception(exc)
  File "C:\Users\takud\OneDrive\Documents\Development\Intelli-Pos\intelliPos\venv\lib\site-packages\rest_framework\views.py", line 469, in handle_exception
    self.raise_uncaught_exception(exc)
  File "C:\Users\takud\OneDrive\Documents\Development\Intelli-Pos\intelliPos\venv\lib\site-packages\rest_framework\views.py", line 480, in raise_uncaught_exception
    raise exc
  File "C:\Users\takud\OneDrive\Documents\Development\Intelli-Pos\intelliPos\venv\lib\site-packages\rest_framework\views.py", line 506, in dispatch
    response = handler(request, *args, **kwargs)
  File "C:\Users\takud\OneDrive\Documents\Development\Intelli-Pos\intelliPos\api\views.py", line 101, in post
    if password_used(user, password):
  File "C:\Users\takud\OneDrive\Documents\Development\Intelli-Pos\intelliPos\api\helper_functions.py", line 12, in password_used
    print(bcrypt.checkpw(new_password, user.password.encode("utf-8")))
  File "C:\Users\takud\OneDrive\Documents\Development\Intelli-Pos\intelliPos\venv\lib\site-packages\bcrypt\__init__.py", line 120, in checkpw
    raise TypeError("Unicode-objects must be encoded before checking")
TypeError: Unicode-objects must be encoded before checking
"POST /api/reset-password/ HTTP/1.1" 500 106793
Internal Server Error: /api/reset-password/
Traceback (most recent call last):
  File "C:\Users\takud\OneDrive\Documents\Development\Intelli-Pos\intelliPos\venv\lib\site-packages\django\core\handlers\exception.py", line 47, in inner
    response = get_response(request)
  File "C:\Users\takud\OneDrive\Documents\Development\Intelli-Pos\intelliPos\venv\lib\site-packages\django\core\handlers\base.py", line 181, in _get_response
    response = wrapped_callback(request, *callback_args, **callback_kwargs)
  File "C:\Users\takud\OneDrive\Documents\Development\Intelli-Pos\intelliPos\venv\lib\site-packages\django\views\decorators\csrf.py", line 54, in wrapped_view
    return view_func(*args, **kwargs)
  File "C:\Users\takud\OneDrive\Documents\Development\Intelli-Pos\intelliPos\venv\lib\site-packages\django\views\generic\base.py", line 70, in view
    return self.dispatch(request, *args, **kwargs)
  File "C:\Users\takud\OneDrive\Documents\Development\Intelli-Pos\intelliPos\venv\lib\site-packages\rest_framework\views.py", line 509, in dispatch
    response = self.handle_exception(exc)
  File "C:\Users\takud\OneDrive\Documents\Development\Intelli-Pos\intelliPos\venv\lib\site-packages\rest_framework\views.py", line 469, in handle_exception
    self.raise_uncaught_exception(exc)
  File "C:\Users\takud\OneDrive\Documents\Development\Intelli-Pos\intelliPos\venv\lib\site-packages\rest_framework\views.py", line 480, in raise_uncaught_exception
    raise exc
  File "C:\Users\takud\OneDrive\Documents\Development\Intelli-Pos\intelliPos\venv\lib\site-packages\rest_framework\views.py", line 506, in dispatch
    response = handler(request, *args, **kwargs)
  File "C:\Users\takud\OneDrive\Documents\Development\Intelli-Pos\intelliPos\api\views.py", line 101, in post
    if password_used(user, password):
  File "C:\Users\takud\OneDrive\Documents\Development\Intelli-Pos\intelliPos\api\helper_functions.py", line 14, in password_used
    print(bcrypt.checkpw(new_password.encode("utf-8"), user.password.encode("utf-8")))
  File "C:\Users\takud\OneDrive\Documents\Development\Intelli-Pos\intelliPos\venv\lib\site-packages\bcrypt\__init__.py", line 127, in checkpw
    ret = hashpw(password, hashed_password)
  File "C:\Users\takud\OneDrive\Documents\Development\Intelli-Pos\intelliPos\venv\lib\site-packages\bcrypt\__init__.py", line 105, in hashpw
    raise ValueError("Invalid salt")
ValueError: Invalid salt
"POST /api/reset-password/ HTTP/1.1" 500 111504
Internal Server Error: /api/reset-password/
Traceback (most recent call last):
  File "C:\Users\takud\OneDrive\Documents\Development\Intelli-Pos\intelliPos\venv\lib\site-packages\django\core\handlers\exception.py", line 47, in inner
    response = get_response(request)
  File "C:\Users\takud\OneDrive\Documents\Development\Intelli-Pos\intelliPos\venv\lib\site-packages\django\core\handlers\base.py", line 181, in _get_response
    response = wrapped_callback(request, *callback_args, **callback_kwargs)
  File "C:\Users\takud\OneDrive\Documents\Development\Intelli-Pos\intelliPos\venv\lib\site-packages\django\views\decorators\csrf.py", line 54, in wrapped_view
    return view_func(*args, **kwargs)
  File "C:\Users\takud\OneDrive\Documents\Development\Intelli-Pos\intelliPos\venv\lib\site-packages\django\views\generic\base.py", line 70, in view
    return self.dispatch(request, *args, **kwargs)
  File "C:\Users\takud\OneDrive\Documents\Development\Intelli-Pos\intelliPos\venv\lib\site-packages\rest_framework\views.py", line 509, in dispatch
    response = self.handle_exception(exc)
  File "C:\Users\takud\OneDrive\Documents\Development\Intelli-Pos\intelliPos\venv\lib\site-packages\rest_framework\views.py", line 469, in handle_exception
    self.raise_uncaught_exception(exc)
  File "C:\Users\takud\OneDrive\Documents\Development\Intelli-Pos\intelliPos\venv\lib\site-packages\rest_framework\views.py", line 480, in raise_uncaught_exception
    raise exc
  File "C:\Users\takud\OneDrive\Documents\Development\Intelli-Pos\intelliPos\venv\lib\site-packages\rest_framework\views.py", line 506, in dispatch
    response = handler(request, *args, **kwargs)
  File "C:\Users\takud\OneDrive\Documents\Development\Intelli-Pos\intelliPos\api\views.py", line 100, in post
    if password_used(user, data.encode('utf-8')):
  File "C:\Users\takud\OneDrive\Documents\Development\Intelli-Pos\intelliPos\api\helper_functions.py", line 15, in password_used
    print(new_password.encode("utf-8"))
AttributeError: 'bytes' object has no attribute 'encode'
"POST /api/reset-password/ HTTP/1.1" 500 103143
Internal Server Error: /api/reset-password/
Traceback (most recent call last):
  File "C:\Users\takud\OneDrive\Documents\Development\Intelli-Pos\intelliPos\venv\lib\site-packages\django\core\handlers\exception.py", line 47, in inner
    response = get_response(request)
  File "C:\Users\takud\OneDrive\Documents\Development\Intelli-Pos\intelliPos\venv\lib\site-packages\django\core\handlers\base.py", line 181, in _get_response
    response = wrapped_callback(request, *callback_args, **callback_kwargs)
  File "C:\Users\takud\OneDrive\Documents\Development\Intelli-Pos\intelliPos\venv\lib\site-packages\django\views\decorators\csrf.py", line 54, in wrapped_view
    return view_func(*args, **kwargs)
  File "C:\Users\takud\OneDrive\Documents\Development\Intelli-Pos\intelliPos\venv\lib\site-packages\django\views\generic\base.py", line 70, in view
    return self.dispatch(request, *args, **kwargs)
  File "C:\Users\takud\OneDrive\Documents\Development\Intelli-Pos\intelliPos\venv\lib\site-packages\rest_framework\views.py", line 509, in dispatch
    response = self.handle_exception(exc)
  File "C:\Users\takud\OneDrive\Documents\Development\Intelli-Pos\intelliPos\venv\lib\site-packages\rest_framework\views.py", line 469, in handle_exception
    self.raise_uncaught_exception(exc)
  File "C:\Users\takud\OneDrive\Documents\Development\Intelli-Pos\intelliPos\venv\lib\site-packages\rest_framework\views.py", line 480, in raise_uncaught_exception
    raise exc
  File "C:\Users\takud\OneDrive\Documents\Development\Intelli-Pos\intelliPos\venv\lib\site-packages\rest_framework\views.py", line 506, in dispatch
    response = handler(request, *args, **kwargs)
  File "C:\Users\takud\OneDrive\Documents\Development\Intelli-Pos\intelliPos\api\views.py", line 100, in post
    if password_used(user, data.encode('utf8')):
  File "C:\Users\takud\OneDrive\Documents\Development\Intelli-Pos\intelliPos\api\helper_functions.py", line 15, in password_used
    print(new_password.encode("utf-8"))
AttributeError: 'bytes' object has no attribute 'encode'
"POST /api/reset-password/ HTTP/1.1" 500 103141
Internal Server Error: /api/reset-password/
Traceback (most recent call last):
  File "C:\Users\takud\OneDrive\Documents\Development\Intelli-Pos\intelliPos\venv\lib\site-packages\django\core\handlers\exception.py", line 47, in inner
    response = get_response(request)
  File "C:\Users\takud\OneDrive\Documents\Development\Intelli-Pos\intelliPos\venv\lib\site-packages\django\core\handlers\base.py", line 181, in _get_response
    response = wrapped_callback(request, *callback_args, **callback_kwargs)
  File "C:\Users\takud\OneDrive\Documents\Development\Intelli-Pos\intelliPos\venv\lib\site-packages\django\views\decorators\csrf.py", line 54, in wrapped_view
    return view_func(*args, **kwargs)
  File "C:\Users\takud\OneDrive\Documents\Development\Intelli-Pos\intelliPos\venv\lib\site-packages\django\views\generic\base.py", line 70, in view
    return self.dispatch(request, *args, **kwargs)
  File "C:\Users\takud\OneDrive\Documents\Development\Intelli-Pos\intelliPos\venv\lib\site-packages\rest_framework\views.py", line 509, in dispatch
    response = self.handle_exception(exc)
  File "C:\Users\takud\OneDrive\Documents\Development\Intelli-Pos\intelliPos\venv\lib\site-packages\rest_framework\views.py", line 469, in handle_exception
    self.raise_uncaught_exception(exc)
  File "C:\Users\takud\OneDrive\Documents\Development\Intelli-Pos\intelliPos\venv\lib\site-packages\rest_framework\views.py", line 480, in raise_uncaught_exception
    raise exc
  File "C:\Users\takud\OneDrive\Documents\Development\Intelli-Pos\intelliPos\venv\lib\site-packages\rest_framework\views.py", line 506, in dispatch
    response = handler(request, *args, **kwargs)
  File "C:\Users\takud\OneDrive\Documents\Development\Intelli-Pos\intelliPos\api\views.py", line 100, in post
    if password_used(user, data.encode('utf8')):
  File "C:\Users\takud\OneDrive\Documents\Development\Intelli-Pos\intelliPos\api\helper_functions.py", line 17, in password_used
    if bcrypt.checkpw(new_password.encode("utf-8"), user.password.encode("utf-8")):
AttributeError: 'bytes' object has no attribute 'encode'
"POST /api/reset-password/ HTTP/1.1" 500 103211
Internal Server Error: /api/login/
"POST /api/login/?username=timothy HTTP/1.1" 500 30
Internal Server Error: /api/login/
"POST /api/login/?username=timothy HTTP/1.1" 500 30
Internal Server Error: /api/login/
"POST /api/login/?username=timothy HTTP/1.1" 500 30
